Workbook

Sheet Datos
A1: Responsable | B1: ITEM | C1: Nombre de tarea | D1: Duración (hábil L-V) | E1: Días Corridos | F1: Comienzo | G1: Fin | H1: N° días hábiles (calc.)
C2: C / OC / DEMOLICIONES GENERALES | D2: 26 días | E2: 37 días | F2: 46266 | G2: 46302 | H2: 27
B3: 1.2.4.1.3 | C3: C / F1 / OC / DEMOLICIONES | D3: 10 días | E3: 15 días | F3: 46276 | G3: 46290 | H3: 11
A4: JONATHAN VERGARA | B4: 1.2.4.1.3.1 | C4: [M2] C / F1 / OC / DEM / Demolición Sector Estanque | D4: 10 días | E4: 15 días | F4: 46276 | G4: 46290 | H4: 11
C5: C / F2 / OC / DEMOLICIONES | D5: 22 días | E5: 31 días | F5: 46266 | G5: 46296 | H5: 23
B6: 1.2.5.1.2 | C6: C / F2 / OC / DEMOLICIONES SUBTERRÁNEO CICLO 01 | D6: 15 días | E6: 22 días | F6: 46272 | G6: 46293 | H6: 16
A7: MAURICIO CONTRERAS | B7: 1.2.5.1.2.4 | C7: [M2] C / F2 / OC / DEMSUB / Demoliciones Cámaras PEAS & Desgrasadora PEAS 3-4 | D7: 7 días | E7: 9 días | F7: 46272 | G7: 46280 | H7: 7
A8: MAURICIO CONTRERAS | B8: 1.2.5.1.2.2 | C8: [M2] C / F2 / OC / DEMSUB / Demoliciones Cámaras A.LL | D8: 5 días | E8: 7 días | F8: 46276 | G8: 46282 | H8: 5
A9: JORGE REYES | B9: 1.2.5.1.2.3 | C9: [M2] C / F2 / OC / DEMSUB / Demoliciones Losa de Fundación F1 | D9: 10 días | E9: 15 días | F9: 46279 | G9: 46293 | H9: 11
B10: 1.2.5.1.3 | C10: C / F2 / OC / DEMOLICIONES SUBTERRÁNEO CICLO 02 | D10: 22 días | E10: 31 días | F10: 46266 | G10: 46296 | H10: 23
A11: MAURICIO CONTRERAS | B11: 1.2.5.1.3.6 | C11: [M2] C / F2 / OC / DEMSUB / Demoliciones Cámaras PEAS & Desgrasadora PEAS 1-2 | D11: 7 días | E11: 9 días | F11: 46286 | G11: 46294 | H11: 7
A12: MAURICIO CONTRERAS | B12: 1.2.5.1.3.2 | C12: [M2] C / F2 / OC / DEMSUB / Demoliciones Cámaras A.LL | D12: 5 días | E12: 5 días | F12: 46286 | G12: 46290 | H12: 5
A13: JORGE REYES | B13: 1.2.5.1.3.3 | C13: [M2] C / F2 / OC / DEMSUB / Demoliciones Losa de Fundación F4 | D13: 9 días | E13: 11 días | F13: 46266 | G13: 46276 | H13: 9
A14: JORGE REYES | B14: 1.2.5.1.3.4 | C14: [M2] C / F2 / OC / DEMSUB / Demolición Muros y Losa | D14: 8 días | E14: 11 días | F14: 46279 | G14: 46289 | H14: 9
A15: JORGE REYES | B15: 1.2.5.1.3.5 | C15: [M2] C / F2 / OC / DEMSUB / Demolición Rampa | D15: 5 días | E15: 7 días | F15: 46290 | G15: 46296 | H15: 5
C16: C / F3 / OC / DEMOLICIONES | D16: 17 días | E16: 24 días | F16: 46279 | G16: 46302 | H16: 18
B17: 1.2.6.1.3 | C17: C / F3 / OC / DEMOLICIONES SUPERFICIE | D17: 17 días | E17: 24 días | F17: 46279 | G17: 46302 | H17: 18
A18: JORGE REYES | B18: 1.2.6.1.3.1 | C18: [M3] C / F3 / OC / DEMSUP / Demolición Vigas de Borde Losa Existente | D18: 7 días | E18: 10 días | F18: 46279 | G18: 46288 | H18: 8
A19: JORGE REYES | B19: 1.2.6.1.3.2.1 | C19: [M2] C / F3 / OC / DEMSUP / Demolición veredas | D19: 3 días | E19: 5 días | F19: 46289 | G19: 46293 | H19: 3
A20: JORGE REYES | B20: 1.2.6.1.3.2.2 | C20: [M2] C / F3 / OC / DEMSUP / Demolición jardinería | D20: 3 días | E20: 5 días | F20: 46289 | G20: 46293 | H20: 3
A21: JORGE REYES | B21: 1.2.6.1.3.3 | C21: [M2] C / F3 / OC / DEMSUP / Demolición de Losas Existentes para Escaleras | D21: 7 días | E21: 9 días | F21: 46294 | G21: 46302 | H21: 7
B22: 1.2.6.1.4 | C22: C / F3 / OC / DEMOLICIONES CUBIERTA | D22: 15 días | E22: 22 días | F22: 46279 | G22: 46300 | H22: 16
A23: JORGE REYES | B23: 1.2.6.1.4.1 | C23: [UN] C / / F3 / OC / DEMCUB / Retiro elementos varios | D23: 5 días | E23: 8 días | F23: 46279 | G23: 46286 | H23: 6
A24: JORGE REYES | B24: 1.2.6.1.4.2 | C24: [M2] C / / F3 / OC / DEMCUB / Demolición alero Falabella lado Norte | D24: 10 días | E24: 14 días | F24: 46287 | G24: 46300 | H24: 10
A25: JORGE REYES | B25: 1.2.6.1.4.3 | C25: [M2] C / / F3 / OC / DEMCUB / Demolición alero Falabella lado Sur | D25: 10 días | E25: 14 días | F25: 46287 | G25: 46300 | H25: 10

Sheet Avance Diario
G1: S02 | H1: S02 | I1: S02 | J1: S02 | K1: S02 | L1: S02 | M1: S03 | N1: S03 | O1: S03 | P1: S03 | Q1: S03 | R1: S03 | S1: S03 | T1: S04 | U1: S04 | V1: S04 | W1: S04 | X1: S04 | Y1: S04 | Z1: S04 | AA1: S05 | AB1: S05 | AC1: S05 | AD1: S05 | AE1: S05 | AF1: S05 | AG1: S05 | AH1: S06 | AI1: S06 | AJ1: S06 | AK1: S06 | AL1: S06 | AM1: S06 | AN1: S06 | AO1: S07 | AP1: S07 | AQ1: S07
G2: 46266 | H2: 46267 | I2: 46268 | J2: 46269 | K2: 46270 | L2: 46271 | M2: 46272 | N2: 46273 | O2: 46274 | P2: 46275 | Q2: 46276 | R2: 46277 | S2: 46278 | T2: 46279 | U2: 46280 | V2: 46281 | W2: 46282 | X2: 46283 | Y2: 46284 | Z2: 46285 | AA2: 46286 | AB2: 46287 | AC2: 46288 | AD2: 46289 | AE2: 46290 | AF2: 46291 | AG2: 46292 | AH2: 46293 | AI2: 46294 | AJ2: 46295 | AK2: 46296 | AL2: 46297 | AM2: 46298 | AN2: 46299 | AO2: 46300 | AP2: 46301 | AQ2: 46302
B3: C / OC / DEMOLICIONES GENERALES | C3: 46266 | D3: 46302 | E3: 27 | F3: Avance parcial % | G3: =IF(AND(G$2>=$C3,G$2<=$D3,WEEKDAY(G$2,2)<=5),100/$E3,0) -> 3.7037037 | H3: =IF(AND(H$2>=$C3,H$2<=$D3,WEEKDAY(H$2,2)<=5),100/$E3,0) -> 3.7037037 | I3: =IF(AND(I$2>=$C3,I$2<=$D3,WEEKDAY(I$2,2)<=5),100/$E3,0) -> 3.7037037 | J3: =IF(AND(J$2>=$C3,J$2<=$D3,WEEKDAY(J$2,2)<=5),100/$E3,0) -> 3.7037037 | K3: =IF(AND(K$2>=$C3,K$2<=$D3,WEEKDAY(K$2,2)<=5),100/$E3,0) -> 0 | L3: =IF(AND(L$2>=$C3,L$2<=$D3,WEEKDAY(L$2,2)<=5),100/$E3,0) -> 0 | M3: =IF(AND(M$2>=$C3,M$2<=$D3,WEEKDAY(M$2,2)<=5),100/$E3,0) -> 3.7037037 | N3: =IF(AND(N$2>=$C3,N$2<=$D3,WEEKDAY(N$2,2)<=5),100/$E3,0) -> 3.7037037 | ... AQ3: =IF(AND(AQ$2>=$C3,AQ$2<=$D3,WEEKDAY(AQ$2,2)<=5),100/$E3,0) -> 3.7037037
F4: Avance acumulado % | G4: =SUM($G3:G3) -> 3.7037037 | H4: =SUM($G3:H3) -> 7.4074074 | I4: =SUM($G3:I3) -> 11.111111 | J4: =SUM($G3:J3) -> 14.814815 | K4: =SUM($G3:K3) -> 14.814815 | L4: =SUM($G3:L3) -> 14.814815 | M4: =SUM($G3:M3) -> 18.518519 | N4: =SUM($G3:N3) -> 22.222222 | ... AQ4: =SUM($G3:AQ3) -> 100
A5: 1.2.4.1.3 | B5: C / F1 / OC / DEMOLICIONES | C5: 46276 | D5: 46290 | E5: 11 | F5: Avance parcial % | G5: =IF(AND(G$2>=$C5,G$2<=$D5,WEEKDAY(G$2,2)<=5),100/$E5,0) -> 0 | H5: =IF(AND(H$2>=$C5,H$2<=$D5,WEEKDAY(H$2,2)<=5),100/$E5,0) -> 0 | I5: =IF(AND(I$2>=$C5,I$2<=$D5,WEEKDAY(I$2,2)<=5),100/$E5,0) -> 0 | J5: =IF(AND(J$2>=$C5,J$2<=$D5,WEEKDAY(J$2,2)<=5),100/$E5,0) -> 0 | K5: =IF(AND(K$2>=$C5,K$2<=$D5,WEEKDAY(K$2,2)<=5),100/$E5,0) -> 0 | L5: =IF(AND(L$2>=$C5,L$2<=$D5,WEEKDAY(L$2,2)<=5),100/$E5,0) -> 0 | M5: =IF(AND(M$2>=$C5,M$2<=$D5,WEEKDAY(M$2,2)<=5),100/$E5,0) -> 0 | N5: =IF(AND(N$2>=$C5,N$2<=$D5,WEEKDAY(N$2,2)<=5),100/$E5,0) -> 0 | ... AQ5: =IF(AND(AQ$2>=$C5,AQ$2<=$D5,WEEKDAY(AQ$2,2)<=5),100/$E5,0) -> 0
F6: Avance acumulado % | G6: =SUM($G5:G5) -> 0 | H6: =SUM($G5:H5) -> 0 | I6: =SUM($G5:I5) -> 0 | J6: =SUM($G5:J5) -> 0 | K6: =SUM($G5:K5) -> 0 | L6: =SUM($G5:L5) -> 0 | M6: =SUM($G5:M5) -> 0 | N6: =SUM($G5:N5) -> 0 | ... AQ6: =SUM($G5:AQ5) -> 100
A7: 1.2.4.1.3.1 | B7: [M2] C / F1 / OC / DEM / Demolición Sector Estanque | C7: 46276 | D7: 46290 | E7: 11 | F7: Avance parcial % | G7: =IF(AND(G$2>=$C7,G$2<=$D7,WEEKDAY(G$2,2)<=5),100/$E7,0) -> 0 | H7: =IF(AND(H$2>=$C7,H$2<=$D7,WEEKDAY(H$2,2)<=5),100/$E7,0) -> 0 | I7: =IF(AND(I$2>=$C7,I$2<=$D7,WEEKDAY(I$2,2)<=5),100/$E7,0) -> 0 | J7: =IF(AND(J$2>=$C7,J$2<=$D7,WEEKDAY(J$2,2)<=5),100/$E7,0) -> 0 | K7: =IF(AND(K$2>=$C7,K$2<=$D7,WEEKDAY(K$2,2)<=5),100/$E7,0) -> 0 | L7: =IF(AND(L$2>=$C7,L$2<=$D7,WEEKDAY(L$2,2)<=5),100/$E7,0) -> 0 | M7: =IF(AND(M$2>=$C7,M$2<=$D7,WEEKDAY(M$2,2)<=5),100/$E7,0) -> 0 | N7: =IF(AND(N$2>=$C7,N$2<=$D7,WEEKDAY(N$2,2)<=5),100/$E7,0) -> 0 | ... AQ7: =IF(AND(AQ$2>=$C7,AQ$2<=$D7,WEEKDAY(AQ$2,2)<=5),100/$E7,0) -> 0
F8: Avance acumulado % | G8: =SUM($G7:G7) -> 0 | H8: =SUM($G7:H7) -> 0 | I8: =SUM($G7:I7) -> 0 | J8: =SUM($G7:J7) -> 0 | K8: =SUM($G7:K7) -> 0 | L8: =SUM($G7:L7) -> 0 | M8: =SUM($G7:M7) -> 0 | N8: =SUM($G7:N7) -> 0 | ... AQ8: =SUM($G7:AQ7) -> 100
B9: C / F2 / OC / DEMOLICIONES | C9: 46266 | D9: 46296 | E9: 23 | F9: Avance parcial % | G9: =IF(AND(G$2>=$C9,G$2<=$D9,WEEKDAY(G$2,2)<=5),100/$E9,0) -> 4.3478261 | H9: =IF(AND(H$2>=$C9,H$2<=$D9,WEEKDAY(H$2,2)<=5),100/$E9,0) -> 4.3478261 | I9: =IF(AND(I$2>=$C9,I$2<=$D9,WEEKDAY(I$2,2)<=5),100/$E9,0) -> 4.3478261 | J9: =IF(AND(J$2>=$C9,J$2<=$D9,WEEKDAY(J$2,2)<=5),100/$E9,0) -> 4.3478261 | K9: =IF(AND(K$2>=$C9,K$2<=$D9,WEEKDAY(K$2,2)<=5),100/$E9,0) -> 0 | L9: =IF(AND(L$2>=$C9,L$2<=$D9,WEEKDAY(L$2,2)<=5),100/$E9,0) -> 0 | M9: =IF(AND(M$2>=$C9,M$2<=$D9,WEEKDAY(M$2,2)<=5),100/$E9,0) -> 4.3478261 | N9: =IF(AND(N$2>=$C9,N$2<=$D9,WEEKDAY(N$2,2)<=5),100/$E9,0) -> 4.3478261 | ... AQ9: =IF(AND(AQ$2>=$C9,AQ$2<=$D9,WEEKDAY(AQ$2,2)<=5),100/$E9,0) -> 0
F10: Avance acumulado % | G10: =SUM($G9:G9) -> 4.3478261 | H10: =SUM($G9:H9) -> 8.6956522 | I10: =SUM($G9:I9) -> 13.043478 | J10: =SUM($G9:J9) -> 17.391304 | K10: =SUM($G9:K9) -> 17.391304 | L10: =SUM($G9:L9) -> 17.391304 | M10: =SUM($G9:M9) -> 21.73913 | N10: =SUM($G9:N9) -> 26.086957 | ... AQ10: =SUM($G9:AQ9) -> 100
A11: 1.2.5.1.2 | B11: C / F2 / OC / DEMOLICIONES SUBTERRÁNEO CICLO 01 | C11: 46272 | D11: 46293 | E11: 16 | F11: Avance parcial % | G11: =IF(AND(G$2>=$C11,G$2<=$D11,WEEKDAY(G$2,2)<=5),100/$E11,0) -> 0 | H11: =IF(AND(H$2>=$C11,H$2<=$D11,WEEKDAY(H$2,2)<=5),100/$E11,0) -> 0 | I11: =IF(AND(I$2>=$C11,I$2<=$D11,WEEKDAY(I$2,2)<=5),100/$E11,0) -> 0 | J11: =IF(AND(J$2>=$C11,J$2<=$D11,WEEKDAY(J$2,2)<=5),100/$E11,0) -> 0 | K11: =IF(AND(K$2>=$C11,K$2<=$D11,WEEKDAY(K$2,2)<=5),100/$E11,0) -> 0 | L11: =IF(AND(L$2>=$C11,L$2<=$D11,WEEKDAY(L$2,2)<=5),100/$E11,0) -> 0 | M11: =IF(AND(M$2>=$C11,M$2<=$D11,WEEKDAY(M$2,2)<=5),100/$E11,0) -> 6.25 | N11: =IF(AND(N$2>=$C11,N$2<=$D11,WEEKDAY(N$2,2)<=5),100/$E11,0) -> 6.25 | ... AQ11: =IF(AND(AQ$2>=$C11,AQ$2<=$D11,WEEKDAY(AQ$2,2)<=5),100/$E11,0) -> 0
F12: Avance acumulado % | G12: =SUM($G11:G11) -> 0 | H12: =SUM($G11:H11) -> 0 | I12: =SUM($G11:I11) -> 0 | J12: =SUM($G11:J11) -> 0 | K12: =SUM($G11:K11) -> 0 | L12: =SUM($G11:L11) -> 0 | M12: =SUM($G11:M11) -> 6.25 | N12: =SUM($G11:N11) -> 12.5 | ... AQ12: =SUM($G11:AQ11) -> 100
A13: 1.2.5.1.2.4 | B13: [M2] C / F2 / OC / DEMSUB / Demoliciones Cámaras PEAS & Desgrasadora PEAS 3-4 | C13: 46272 | D13: 46280 | E13: 7 | F13: Avance parcial % | G13: =IF(AND(G$2>=$C13,G$2<=$D13,WEEKDAY(G$2,2)<=5),100/$E13,0) -> 0 | H13: =IF(AND(H$2>=$C13,H$2<=$D13,WEEKDAY(H$2,2)<=5),100/$E13,0) -> 0 | I13: =IF(AND(I$2>=$C13,I$2<=$D13,WEEKDAY(I$2,2)<=5),100/$E13,0) -> 0 | J13: =IF(AND(J$2>=$C13,J$2<=$D13,WEEKDAY(J$2,2)<=5),100/$E13,0) -> 0 | K13: =IF(AND(K$2>=$C13,K$2<=$D13,WEEKDAY(K$2,2)<=5),100/$E13,0) -> 0 | L13: =IF(AND(L$2>=$C13,L$2<=$D13,WEEKDAY(L$2,2)<=5),100/$E13,0) -> 0 | M13: =IF(AND(M$2>=$C13,M$2<=$D13,WEEKDAY(M$2,2)<=5),100/$E13,0) -> 14.285714 | N13: =IF(AND(N$2>=$C13,N$2<=$D13,WEEKDAY(N$2,2)<=5),100/$E13,0) -> 14.285714 | ... AQ13: =IF(AND(AQ$2>=$C13,AQ$2<=$D13,WEEKDAY(AQ$2,2)<=5),100/$E13,0) -> 0
F14: Avance acumulado % | G14: =SUM($G13:G13) -> 0 | H14: =SUM($G13:H13) -> 0 | I14: =SUM($G13:I13) -> 0 | J14: =SUM($G13:J13) -> 0 | K14: =SUM($G13:K13) -> 0 | L14: =SUM($G13:L13) -> 0 | M14: =SUM($G13:M13) -> 14.285714 | N14: =SUM($G13:N13) -> 28.571429 | ... AQ14: =SUM($G13:AQ13) -> 100
A15: 1.2.5.1.2.2 | B15: [M2] C / F2 / OC / DEMSUB / Demoliciones Cámaras A.LL | C15: 46276 | D15: 46282 | E15: 5 | F15: Avance parcial % | G15: =IF(AND(G$2>=$C15,G$2<=$D15,WEEKDAY(G$2,2)<=5),100/$E15,0) -> 0 | H15: =IF(AND(H$2>=$C15,H$2<=$D15,WEEKDAY(H$2,2)<=5),100/$E15,0) -> 0 | I15: =IF(AND(I$2>=$C15,I$2<=$D15,WEEKDAY(I$2,2)<=5),100/$E15,0) -> 0 | J15: =IF(AND(J$2>=$C15,J$2<=$D15,WEEKDAY(J$2,2)<=5),100/$E15,0) -> 0 | K15: =IF(AND(K$2>=$C15,K$2<=$D15,WEEKDAY(K$2,2)<=5),100/$E15,0) -> 0 | L15: =IF(AND(L$2>=$C15,L$2<=$D15,WEEKDAY(L$2,2)<=5),100/$E15,0) -> 0 | M15: =IF(AND(M$2>=$C15,M$2<=$D15,WEEKDAY(M$2,2)<=5),100/$E15,0) -> 0 | N15: =IF(AND(N$2>=$C15,N$2<=$D15,WEEKDAY(N$2,2)<=5),100/$E15,0) -> 0 | ... AQ15: =IF(AND(AQ$2>=$C15,AQ$2<=$D15,WEEKDAY(AQ$2,2)<=5),100/$E15,0) -> 0
F16: Avance acumulado % | G16: =SUM($G15:G15) -> 0 | H16: =SUM($G15:H15) -> 0 | I16: =SUM($G15:I15) -> 0 | J16: =SUM($G15:J15) -> 0 | K16: =SUM($G15:K15) -> 0 | L16: =SUM($G15:L15) -> 0 | M16: =SUM($G15:M15) -> 0 | N16: =SUM($G15:N15) -> 0 | ... AQ16: =SUM($G15:AQ15) -> 100
A17: 1.2.5.1.2.3 | B17: [M2] C / F2 / OC / DEMSUB / Demoliciones Losa de Fundación F1 | C17: 46279 | D17: 46293 | E17: 11 | F17: Avance parcial % | G17: =IF(AND(G$2>=$C17,G$2<=$D17,WEEKDAY(G$2,2)<=5),100/$E17,0) -> 0 | H17: =IF(AND(H$2>=$C17,H$2<=$D17,WEEKDAY(H$2,2)<=5),100/$E17,0) -> 0 | I17: =IF(AND(I$2>=$C17,I$2<=$D17,WEEKDAY(I$2,2)<=5),100/$E17,0) -> 0 | J17: =IF(AND(J$2>=$C17,J$2<=$D17,WEEKDAY(J$2,2)<=5),100/$E17,0) -> 0 | K17: =IF(AND(K$2>=$C17,K$2<=$D17,WEEKDAY(K$2,2)<=5),100/$E17,0) -> 0 | L17: =IF(AND(L$2>=$C17,L$2<=$D17,WEEKDAY(L$2,2)<=5),100/$E17,0) -> 0 | M17: =IF(AND(M$2>=$C17,M$2<=$D17,WEEKDAY(M$2,2)<=5),100/$E17,0) -> 0 | N17: =IF(AND(N$2>=$C17,N$2<=$D17,WEEKDAY(N$2,2)<=5),100/$E17,0) -> 0 | ... AQ17: =IF(AND(AQ$2>=$C17,AQ$2<=$D17,WEEKDAY(AQ$2,2)<=5),100/$E17,0) -> 0
F18: Avance acumulado % | G18: =SUM($G17:G17) -> 0 | H18: =SUM($G17:H17) -> 0 | I18: =SUM($G17:I17) -> 0 | J18: =SUM($G17:J17) -> 0 | K18: =SUM($G17:K17) -> 0 | L18: =SUM($G17:L17) -> 0 | M18: =SUM($G17:M17) -> 0 | N18: =SUM($G17:N17) -> 0 | ... AQ18: =SUM($G17:AQ17) -> 100
A19: 1.2.5.1.3 | B19: C / F2 / OC / DEMOLICIONES SUBTERRÁNEO CICLO 02 | C19: 46266 | D19: 46296 | E19: 23 | F19: Avance parcial % | G19: =IF(AND(G$2>=$C19,G$2<=$D19,WEEKDAY(G$2,2)<=5),100/$E19,0) -> 4.3478261 | H19: =IF(AND(H$2>=$C19,H$2<=$D19,WEEKDAY(H$2,2)<=5),100/$E19,0) -> 4.3478261 | I19: =IF(AND(I$2>=$C19,I$2<=$D19,WEEKDAY(I$2,2)<=5),100/$E19,0) -> 4.3478261 | J19: =IF(AND(J$2>=$C19,J$2<=$D19,WEEKDAY(J$2,2)<=5),100/$E19,0) -> 4.3478261 | K19: =IF(AND(K$2>=$C19,K$2<=$D19,WEEKDAY(K$2,2)<=5),100/$E19,0) -> 0 | L19: =IF(AND(L$2>=$C19,L$2<=$D19,WEEKDAY(L$2,2)<=5),100/$E19,0) -> 0 | M19: =IF(AND(M$2>=$C19,M$2<=$D19,WEEKDAY(M$2,2)<=5),100/$E19,0) -> 4.3478261 | N19: =IF(AND(N$2>=$C19,N$2<=$D19,WEEKDAY(N$2,2)<=5),100/$E19,0) -> 4.3478261 | ... AQ19: =IF(AND(AQ$2>=$C19,AQ$2<=$D19,WEEKDAY(AQ$2,2)<=5),100/$E19,0) -> 0
F20: Avance acumulado % | G20: =SUM($G19:G19) -> 4.3478261 | H20: =SUM($G19:H19) -> 8.6956522 | I20: =SUM($G19:I19) -> 13.043478 | J20: =SUM($G19:J19) -> 17.391304 | K20: =SUM($G19:K19) -> 17.391304 | L20: =SUM($G19:L19) -> 17.391304 | M20: =SUM($G19:M19) -> 21.73913 | N20: =SUM($G19:N19) -> 26.086957 | ... AQ20: =SUM($G19:AQ19) -> 100
A21: 1.2.5.1.3.6 | B21: [M2] C / F2 / OC / DEMSUB / Demoliciones Cámaras PEAS & Desgrasadora PEAS 1-2 | C21: 46286 | D21: 46294 | E21: 7 | F21: Avance parcial % | G21: =IF(AND(G$2>=$C21,G$2<=$D21,WEEKDAY(G$2,2)<=5),100/$E21,0) -> 0 | H21: =IF(AND(H$2>=$C21,H$2<=$D21,WEEKDAY(H$2,2)<=5),100/$E21,0) -> 0 | I21: =IF(AND(I$2>=$C21,I$2<=$D21,WEEKDAY(I$2,2)<=5),100/$E21,0) -> 0 | J21: =IF(AND(J$2>=$C21,J$2<=$D21,WEEKDAY(J$2,2)<=5),100/$E21,0) -> 0 | K21: =IF(AND(K$2>=$C21,K$2<=$D21,WEEKDAY(K$2,2)<=5),100/$E21,0) -> 0 | L21: =IF(AND(L$2>=$C21,L$2<=$D21,WEEKDAY(L$2,2)<=5),100/$E21,0) -> 0 | M21: =IF(AND(M$2>=$C21,M$2<=$D21,WEEKDAY(M$2,2)<=5),100/$E21,0) -> 0 | N21: =IF(AND(N$2>=$C21,N$2<=$D21,WEEKDAY(N$2,2)<=5),100/$E21,0) -> 0 | ... AQ21: =IF(AND(AQ$2>=$C21,AQ$2<=$D21,WEEKDAY(AQ$2,2)<=5),100/$E21,0) -> 0
F22: Avance acumulado % | G22: =SUM($G21:G21) -> 0 | H22: =SUM($G21:H21) -> 0 | I22: =SUM($G21:I21) -> 0 | J22: =SUM($G21:J21) -> 0 | K22: =SUM($G21:K21) -> 0 | L22: =SUM($G21:L21) -> 0 | M22: =SUM($G21:M21) -> 0 | N22: =SUM($G21:N21) -> 0 | ... AQ22: =SUM($G21:AQ21) -> 100
A23: 1.2.5.1.3.2 | B23: [M2] C / F2 / OC / DEMSUB / Demoliciones Cámaras A.LL | C23: 46286 | D23: 46290 | E23: 5 | F23: Avance parcial % | G23: =IF(AND(G$2>=$C23,G$2<=$D23,WEEKDAY(G$2,2)<=5),100/$E23,0) -> 0 | H23: =IF(AND(H$2>=$C23,H$2<=$D23,WEEKDAY(H$2,2)<=5),100/$E23,0) -> 0 | I23: =IF(AND(I$2>=$C23,I$2<=$D23,WEEKDAY(I$2,2)<=5),100/$E23,0) -> 0 | J23: =IF(AND(J$2>=$C23,J$2<=$D23,WEEKDAY(J$2,2)<=5),100/$E23,0) -> 0 | K23: =IF(AND(K$2>=$C23,K$2<=$D23,WEEKDAY(K$2,2)<=5),100/$E23,0) -> 0 | L23: =IF(AND(L$2>=$C23,L$2<=$D23,WEEKDAY(L$2,2)<=5),100/$E23,0) -> 0 | M23: =IF(AND(M$2>=$C23,M$2<=$D23,WEEKDAY(M$2,2)<=5),100/$E23,0) -> 0 | N23: =IF(AND(N$2>=$C23,N$2<=$D23,WEEKDAY(N$2,2)<=5),100/$E23,0) -> 0 | ... AQ23: =IF(AND(AQ$2>=$C23,AQ$2<=$D23,WEEKDAY(AQ$2,2)<=5),100/$E23,0) -> 0
F24: Avance acumulado % | G24: =SUM($G23:G23) -> 0 | H24: =SUM($G23:H23) -> 0 | I24: =SUM($G23:I23) -> 0 | J24: =SUM($G23:J23) -> 0 | K24: =SUM($G23:K23) -> 0 | L24: =SUM($G23:L23) -> 0 | M24: =SUM($G23:M23) -> 0 | N24: =SUM($G23:N23) -> 0 | ... AQ24: =SUM($G23:AQ23) -> 100
A25: 1.2.5.1.3.3 | B25: [M2] C / F2 / OC / DEMSUB / Demoliciones Losa de Fundación F4 | C25: 46266 | D25: 46276 | E25: 9 | F25: Avance parcial % | G25: =IF(AND(G$2>=$C25,G$2<=$D25,WEEKDAY(G$2,2)<=5),100/$E25,0) -> 11.111111 | H25: =IF(AND(H$2>=$C25,H$2<=$D25,WEEKDAY(H$2,2)<=5),100/$E25,0) -> 11.111111 | I25: =IF(AND(I$2>=$C25,I$2<=$D25,WEEKDAY(I$2,2)<=5),100/$E25,0) -> 11.111111 | J25: =IF(AND(J$2>=$C25,J$2<=$D25,WEEKDAY(J$2,2)<=5),100/$E25,0) -> 11.111111 | K25: =IF(AND(K$2>=$C25,K$2<=$D25,WEEKDAY(K$2,2)<=5),100/$E25,0) -> 0 | L25: =IF(AND(L$2>=$C25,L$2<=$D25,WEEKDAY(L$2,2)<=5),100/$E25,0) -> 0 | M25: =IF(AND(M$2>=$C25,M$2<=$D25,WEEKDAY(M$2,2)<=5),100/$E25,0) -> 11.111111 | N25: =IF(AND(N$2>=$C25,N$2<=$D25,WEEKDAY(N$2,2)<=5),100/$E25,0) -> 11.111111 | ... AQ25: =IF(AND(AQ$2>=$C25,AQ$2<=$D25,WEEKDAY(AQ$2,2)<=5),100/$E25,0) -> 0
F26: Avance acumulado % | G26: =SUM($G25:G25) -> 11.111111 | H26: =SUM($G25:H25) -> 22.222222 | I26: =SUM($G25:I25) -> 33.333333 | J26: =SUM($G25:J25) -> 44.444444 | K26: =SUM($G25:K25) -> 44.444444 | L26: =SUM($G25:L25) -> 44.444444 | M26: =SUM($G25:M25) -> 55.555556 | N26: =SUM($G25:N25) -> 66.666667 | ... AQ26: =SUM($G25:AQ25) -> 100
A27: 1.2.5.1.3.4 | B27: [M2] C / F2 / OC / DEMSUB / Demolición Muros y Losa | C27: 46279 | D27: 46289 | E27: 9 | F27: Avance parcial % | G27: =IF(AND(G$2>=$C27,G$2<=$D27,WEEKDAY(G$2,2)<=5),100/$E27,0) -> 0 | H27: =IF(AND(H$2>=$C27,H$2<=$D27,WEEKDAY(H$2,2)<=5),100/$E27,0) -> 0 | I27: =IF(AND(I$2>=$C27,I$2<=$D27,WEEKDAY(I$2,2)<=5),100/$E27,0) -> 0 | J27: =IF(AND(J$2>=$C27,J$2<=$D27,WEEKDAY(J$2,2)<=5),100/$E27,0) -> 0 | K27: =IF(AND(K$2>=$C27,K$2<=$D27,WEEKDAY(K$2,2)<=5),100/$E27,0) -> 0 | L27: =IF(AND(L$2>=$C27,L$2<=$D27,WEEKDAY(L$2,2)<=5),100/$E27,0) -> 0 | M27: =IF(AND(M$2>=$C27,M$2<=$D27,WEEKDAY(M$2,2)<=5),100/$E27,0) -> 0 | N27: =IF(AND(N$2>=$C27,N$2<=$D27,WEEKDAY(N$2,2)<=5),100/$E27,0) -> 0 | ... AQ27: =IF(AND(AQ$2>=$C27,AQ$2<=$D27,WEEKDAY(AQ$2,2)<=5),100/$E27,0) -> 0
F28: Avance acumulado % | G28: =SUM($G27:G27) -> 0 | H28: =SUM($G27:H27) -> 0 | I28: =SUM($G27:I27) -> 0 | J28: =SUM($G27:J27) -> 0 | K28: =SUM($G27:K27) -> 0 | L28: =SUM($G27:L27) -> 0 | M28: =SUM($G27:M27) -> 0 | N28: =SUM($G27:N27) -> 0 | ... AQ28: =SUM($G27:AQ27) -> 100
A29: 1.2.5.1.3.5 | B29: [M2] C / F2 / OC / DEMSUB / Demolición Rampa | C29: 46290 | D29: 46296 | E29: 5 | F29: Avance parcial % | G29: =IF(AND(G$2>=$C29,G$2<=$D29,WEEKDAY(G$2,2)<=5),100/$E29,0) -> 0 | H29: =IF(AND(H$2>=$C29,H$2<=$D29,WEEKDAY(H$2,2)<=5),100/$E29,0) -> 0 | I29: =IF(AND(I$2>=$C29,I$2<=$D29,WEEKDAY(I$2,2)<=5),100/$E29,0) -> 0 | J29: =IF(AND(J$2>=$C29,J$2<=$D29,WEEKDAY(J$2,2)<=5),100/$E29,0) -> 0 | K29: =IF(AND(K$2>=$C29,K$2<=$D29,WEEKDAY(K$2,2)<=5),100/$E29,0) -> 0 | L29: =IF(AND(L$2>=$C29,L$2<=$D29,WEEKDAY(L$2,2)<=5),100/$E29,0) -> 0 | M29: =IF(AND(M$2>=$C29,M$2<=$D29,WEEKDAY(M$2,2)<=5),100/$E29,0) -> 0 | N29: =IF(AND(N$2>=$C29,N$2<=$D29,WEEKDAY(N$2,2)<=5),100/$E29,0) -> 0 | ... AQ29: =IF(AND(AQ$2>=$C29,AQ$2<=$D29,WEEKDAY(AQ$2,2)<=5),100/$E29,0) -> 0
F30: Avance acumulado % | G30: =SUM($G29:G29) -> 0 | H30: =SUM($G29:H29) -> 0 | I30: =SUM($G29:I29) -> 0 | J30: =SUM($G29:J29) -> 0 | K30: =SUM($G29:K29) -> 0 | L30: =SUM($G29:L29) -> 0 | M30: =SUM($G29:M29) -> 0 | N30: =SUM($G29:N29) -> 0 | ... AQ30: =SUM($G29:AQ29) -> 100
B31: C / F3 / OC / DEMOLICIONES | C31: 46279 | D31: 46302 | E31: 18 | F31: Avance parcial % | G31: =IF(AND(G$2>=$C31,G$2<=$D31,WEEKDAY(G$2,2)<=5),100/$E31,0) -> 0 | H31: =IF(AND(H$2>=$C31,H$2<=$D31,WEEKDAY(H$2,2)<=5),100/$E31,0) -> 0 | I31: =IF(AND(I$2>=$C31,I$2<=$D31,WEEKDAY(I$2,2)<=5),100/$E31,0) -> 0 | J31: =IF(AND(J$2>=$C31,J$2<=$D31,WEEKDAY(J$2,2)<=5),100/$E31,0) -> 0 | K31: =IF(AND(K$2>=$C31,K$2<=$D31,WEEKDAY(K$2,2)<=5),100/$E31,0) -> 0 | L31: =IF(AND(L$2>=$C31,L$2<=$D31,WEEKDAY(L$2,2)<=5),100/$E31,0) -> 0 | M31: =IF(AND(M$2>=$C31,M$2<=$D31,WEEKDAY(M$2,2)<=5),100/$E31,0) -> 0 | N31: =IF(AND(N$2>=$C31,N$2<=$D31,WEEKDAY(N$2,2)<=5),100/$E31,0) -> 0 | ... AQ31: =IF(AND(AQ$2>=$C31,AQ$2<=$D31,WEEKDAY(AQ$2,2)<=5),100/$E31,0) -> 5.5555556
F32: Avance acumulado % | G32: =SUM($G31:G31) -> 0 | H32: =SUM($G31:H31) -> 0 | I32: =SUM($G31:I31) -> 0 | J32: =SUM($G31:J31) -> 0 | K32: =SUM($G31:K31) -> 0 | L32: =SUM($G31:L31) -> 0 | M32: =SUM($G31:M31) -> 0 | N32: =SUM($G31:N31) -> 0 | ... AQ32: =SUM($G31:AQ31) -> 100
A33: 1.2.6.1.3 | B33: C / F3 / OC / DEMOLICIONES SUPERFICIE | C33: 46279 | D33: 46302 | E33: 18 | F33: Avance parcial % | G33: =IF(AND(G$2>=$C33,G$2<=$D33,WEEKDAY(G$2,2)<=5),100/$E33,0) -> 0 | H33: =IF(AND(H$2>=$C33,H$2<=$D33,WEEKDAY(H$2,2)<=5),100/$E33,0) -> 0 | I33: =IF(AND(I$2>=$C33,I$2<=$D33,WEEKDAY(I$2,2)<=5),100/$E33,0) -> 0 | J33: =IF(AND(J$2>=$C33,J$2<=$D33,WEEKDAY(J$2,2)<=5),100/$E33,0) -> 0 | K33: =IF(AND(K$2>=$C33,K$2<=$D33,WEEKDAY(K$2,2)<=5),100/$E33,0) -> 0 | L33: =IF(AND(L$2>=$C33,L$2<=$D33,WEEKDAY(L$2,2)<=5),100/$E33,0) -> 0 | M33: =IF(AND(M$2>=$C33,M$2<=$D33,WEEKDAY(M$2,2)<=5),100/$E33,0) -> 0 | N33: =IF(AND(N$2>=$C33,N$2<=$D33,WEEKDAY(N$2,2)<=5),100/$E33,0) -> 0 | ... AQ33: =IF(AND(AQ$2>=$C33,AQ$2<=$D33,WEEKDAY(AQ$2,2)<=5),100/$E33,0) -> 5.5555556
F34: Avance acumulado % | G34: =SUM($G33:G33) -> 0 | H34: =SUM($G33:H33) -> 0 | I34: =SUM($G33:I33) -> 0 | J34: =SUM($G33:J33) -> 0 | K34: =SUM($G33:K33) -> 0 | L34: =SUM($G33:L33) -> 0 | M34: =SUM($G33:M33) -> 0 | N34: =SUM($G33:N33) -> 0 | ... AQ34: =SUM($G33:AQ33) -> 100
A35: 1.2.6.1.3.1 | B35: [M3] C / F3 / OC / DEMSUP / Demolición Vigas de Borde Losa Existente | C35: 46279 | D35: 46288 | E35: 8 | F35: Avance parcial % | G35: =IF(AND(G$2>=$C35,G$2<=$D35,WEEKDAY(G$2,2)<=5),100/$E35,0) -> 0 | H35: =IF(AND(H$2>=$C35,H$2<=$D35,WEEKDAY(H$2,2)<=5),100/$E35,0) -> 0 | I35: =IF(AND(I$2>=$C35,I$2<=$D35,WEEKDAY(I$2,2)<=5),100/$E35,0) -> 0 | J35: =IF(AND(J$2>=$C35,J$2<=$D35,WEEKDAY(J$2,2)<=5),100/$E35,0) -> 0 | K35: =IF(AND(K$2>=$C35,K$2<=$D35,WEEKDAY(K$2,2)<=5),100/$E35,0) -> 0 | L35: =IF(AND(L$2>=$C35,L$2<=$D35,WEEKDAY(L$2,2)<=5),100/$E35,0) -> 0 | M35: =IF(AND(M$2>=$C35,M$2<=$D35,WEEKDAY(M$2,2)<=5),100/$E35,0) -> 0 | N35: =IF(AND(N$2>=$C35,N$2<=$D35,WEEKDAY(N$2,2)<=5),100/$E35,0) -> 0 | ... AQ35: =IF(AND(AQ$2>=$C35,AQ$2<=$D35,WEEKDAY(AQ$2,2)<=5),100/$E35,0) -> 0
F36: Avance acumulado % | G36: =SUM($G35:G35) -> 0 | H36: =SUM($G35:H35) -> 0 | I36: =SUM($G35:I35) -> 0 | J36: =SUM($G35:J35) -> 0 | K36: =SUM($G35:K35) -> 0 | L36: =SUM($G35:L35) -> 0 | M36: =SUM($G35:M35) -> 0 | N36: =SUM($G35:N35) -> 0 | ... AQ36: =SUM($G35:AQ35) -> 100
A37: 1.2.6.1.3.2.1 | B37: [M2] C / F3 / OC / DEMSUP / Demolición veredas | C37: 46289 | D37: 46293 | E37: 3 | F37: Avance parcial % | G37: =IF(AND(G$2>=$C37,G$2<=$D37,WEEKDAY(G$2,2)<=5),100/$E37,0) -> 0 | H37: =IF(AND(H$2>=$C37,H$2<=$D37,WEEKDAY(H$2,2)<=5),100/$E37,0) -> 0 | I37: =IF(AND(I$2>=$C37,I$2<=$D37,WEEKDAY(I$2,2)<=5),100/$E37,0) -> 0 | J37: =IF(AND(J$2>=$C37,J$2<=$D37,WEEKDAY(J$2,2)<=5),100/$E37,0) -> 0 | K37: =IF(AND(K$2>=$C37,K$2<=$D37,WEEKDAY(K$2,2)<=5),100/$E37,0) -> 0 | L37: =IF(AND(L$2>=$C37,L$2<=$D37,WEEKDAY(L$2,2)<=5),100/$E37,0) -> 0 | M37: =IF(AND(M$2>=$C37,M$2<=$D37,WEEKDAY(M$2,2)<=5),100/$E37,0) -> 0 | N37: =IF(AND(N$2>=$C37,N$2<=$D37,WEEKDAY(N$2,2)<=5),100/$E37,0) -> 0 | ... AQ37: =IF(AND(AQ$2>=$C37,AQ$2<=$D37,WEEKDAY(AQ$2,2)<=5),100/$E37,0) -> 0
F38: Avance acumulado % | G38: =SUM($G37:G37) -> 0 | H38: =SUM($G37:H37) -> 0 | I38: =SUM($G37:I37) -> 0 | J38: =SUM($G37:J37) -> 0 | K38: =SUM($G37:K37) -> 0 | L38: =SUM($G37:L37) -> 0 | M38: =SUM($G37:M37) -> 0 | N38: =SUM($G37:N37) -> 0 | ... AQ38: =SUM($G37:AQ37) -> 100
A39: 1.2.6.1.3.2.2 | B39: [M2] C / F3 / OC / DEMSUP / Demolición jardinería | C39: 46289 | D39: 46293 | E39: 3 | F39: Avance parcial % | G39: =IF(AND(G$2>=$C39,G$2<=$D39,WEEKDAY(G$2,2)<=5),100/$E39,0) -> 0 | H39: =IF(AND(H$2>=$C39,H$2<=$D39,WEEKDAY(H$2,2)<=5),100/$E39,0) -> 0 | I39: =IF(AND(I$2>=$C39,I$2<=$D39,WEEKDAY(I$2,2)<=5),100/$E39,0) -> 0 | J39: =IF(AND(J$2>=$C39,J$2<=$D39,WEEKDAY(J$2,2)<=5),100/$E39,0) -> 0 | K39: =IF(AND(K$2>=$C39,K$2<=$D39,WEEKDAY(K$2,2)<=5),100/$E39,0) -> 0 | L39: =IF(AND(L$2>=$C39,L$2<=$D39,WEEKDAY(L$2,2)<=5),100/$E39,0) -> 0 | M39: =IF(AND(M$2>=$C39,M$2<=$D39,WEEKDAY(M$2,2)<=5),100/$E39,0) -> 0 | N39: =IF(AND(N$2>=$C39,N$2<=$D39,WEEKDAY(N$2,2)<=5),100/$E39,0) -> 0 | ... AQ39: =IF(AND(AQ$2>=$C39,AQ$2<=$D39,WEEKDAY(AQ$2,2)<=5),100/$E39,0) -> 0
F40: Avance acumulado % | G40: =SUM($G39:G39) -> 0 | H40: =SUM($G39:H39) -> 0 | I40: =SUM($G39:I39) -> 0 | J40: =SUM($G39:J39) -> 0 | K40: =SUM($G39:K39) -> 0 | L40: =SUM($G39:L39) -> 0 | M40: =SUM($G39:M39) -> 0 | N40: =SUM($G39:N39) -> 0 | ... AQ40: =SUM($G39:AQ39) -> 100
...

Sheet Avance Semanal
A1: ITEM | B1: Actividad | C1: Tipo | D1: S02 31-ago al 06-sep | E1: S03 07-sep al 13-sep | F1: S04 14-sep al 20-sep | G1: S05 21-sep al 27-sep | H1: S06 28-sep al 04-oct | I1: S07 05-oct al 11-oct
B2: C / OC / DEMOLICIONES GENERALES | C2: Avance parcial % | D2: =SUM('Avance Diario'!G3:L3) -> 14.814815 | E2: =SUM('Avance Diario'!M3:S3) -> 18.518519 | F2: =SUM('Avance Diario'!T3:Z3) -> 18.518519 | G2: =SUM('Avance Diario'!AA3:AG3) -> 18.518519 | H2: =SUM('Avance Diario'!AH3:AN3) -> 18.518519 | I2: =SUM('Avance Diario'!AO3:AQ3) -> 11.111111
C3: Avance acumulado % | D3: =SUM($D2:D2) -> 14.814815 | E3: =SUM($D2:E2) -> 33.333333 | F3: =SUM($D2:F2) -> 51.851852 | G3: =SUM($D2:G2) -> 70.37037 | H3: =SUM($D2:H2) -> 88.888889 | I3: =SUM($D2:I2) -> 100
A4: 1.2.4.1.3 | B4: C / F1 / OC / DEMOLICIONES | C4: Avance parcial % | D4: =SUM('Avance Diario'!G5:L5) -> 0 | E4: =SUM('Avance Diario'!M5:S5) -> 9.0909091 | F4: =SUM('Avance Diario'!T5:Z5) -> 45.454545 | G4: =SUM('Avance Diario'!AA5:AG5) -> 45.454545 | H4: =SUM('Avance Diario'!AH5:AN5) -> 0 | I4: =SUM('Avance Diario'!AO5:AQ5) -> 0
C5: Avance acumulado % | D5: =SUM($D4:D4) -> 0 | E5: =SUM($D4:E4) -> 9.0909091 | F5: =SUM($D4:F4) -> 54.545455 | G5: =SUM($D4:G4) -> 100 | H5: =SUM($D4:H4) -> 100 | I5: =SUM($D4:I4) -> 100
A6: 1.2.4.1.3.1 | B6: [M2] C / F1 / OC / DEM / Demolición Sector Estanque | C6: Avance parcial % | D6: =SUM('Avance Diario'!G7:L7) -> 0 | E6: =SUM('Avance Diario'!M7:S7) -> 9.0909091 | F6: =SUM('Avance Diario'!T7:Z7) -> 45.454545 | G6: =SUM('Avance Diario'!AA7:AG7) -> 45.454545 | H6: =SUM('Avance Diario'!AH7:AN7) -> 0 | I6: =SUM('Avance Diario'!AO7:AQ7) -> 0
C7: Avance acumulado % | D7: =SUM($D6:D6) -> 0 | E7: =SUM($D6:E6) -> 9.0909091 | F7: =SUM($D6:F6) -> 54.545455 | G7: =SUM($D6:G6) -> 100 | H7: =SUM($D6:H6) -> 100 | I7: =SUM($D6:I6) -> 100
B8: C / F2 / OC / DEMOLICIONES | C8: Avance parcial % | D8: =SUM('Avance Diario'!G9:L9) -> 17.391304 | E8: =SUM('Avance Diario'!M9:S9) -> 21.73913 | F8: =SUM('Avance Diario'!T9:Z9) -> 21.73913 | G8: =SUM('Avance Diario'!AA9:AG9) -> 21.73913 | H8: =SUM('Avance Diario'!AH9:AN9) -> 17.391304 | I8: =SUM('Avance Diario'!AO9:AQ9) -> 0
C9: Avance acumulado % | D9: =SUM($D8:D8) -> 17.391304 | E9: =SUM($D8:E8) -> 39.130435 | F9: =SUM($D8:F8) -> 60.869565 | G9: =SUM($D8:G8) -> 82.608696 | H9: =SUM($D8:H8) -> 100 | I9: =SUM($D8:I8) -> 100
A10: 1.2.5.1.2 | B10: C / F2 / OC / DEMOLICIONES SUBTERRÁNEO CICLO 01 | C10: Avance parcial % | D10: =SUM('Avance Diario'!G11:L11) -> 0 | E10: =SUM('Avance Diario'!M11:S11) -> 31.25 | F10: =SUM('Avance Diario'!T11:Z11) -> 31.25 | G10: =SUM('Avance Diario'!AA11:AG11) -> 31.25 | H10: =SUM('Avance Diario'!AH11:AN11) -> 6.25 | I10: =SUM('Avance Diario'!AO11:AQ11) -> 0
C11: Avance acumulado % | D11: =SUM($D10:D10) -> 0 | E11: =SUM($D10:E10) -> 31.25 | F11: =SUM($D10:F10) -> 62.5 | G11: =SUM($D10:G10) -> 93.75 | H11: =SUM($D10:H10) -> 100 | I11: =SUM($D10:I10) -> 100
A12: 1.2.5.1.2.4 | B12: [M2] C / F2 / OC / DEMSUB / Demoliciones Cámaras PEAS & Desgrasadora PEAS 3-4 | C12: Avance parcial % | D12: =SUM('Avance Diario'!G13:L13) -> 0 | E12: =SUM('Avance Diario'!M13:S13) -> 71.428571 | F12: =SUM('Avance Diario'!T13:Z13) -> 28.571429 | G12: =SUM('Avance Diario'!AA13:AG13) -> 0 | H12: =SUM('Avance Diario'!AH13:AN13) -> 0 | I12: =SUM('Avance Diario'!AO13:AQ13) -> 0
C13: Avance acumulado % | D13: =SUM($D12:D12) -> 0 | E13: =SUM($D12:E12) -> 71.428571 | F13: =SUM($D12:F12) -> 100 | G13: =SUM($D12:G12) -> 100 | H13: =SUM($D12:H12) -> 100 | I13: =SUM($D12:I12) -> 100
A14: 1.2.5.1.2.2 | B14: [M2] C / F2 / OC / DEMSUB / Demoliciones Cámaras A.LL | C14: Avance parcial % | D14: =SUM('Avance Diario'!G15:L15) -> 0 | E14: =SUM('Avance Diario'!M15:S15) -> 20 | F14: =SUM('Avance Diario'!T15:Z15) -> 80 | G14: =SUM('Avance Diario'!AA15:AG15) -> 0 | H14: =SUM('Avance Diario'!AH15:AN15) -> 0 | I14: =SUM('Avance Diario'!AO15:AQ15) -> 0
C15: Avance acumulado % | D15: =SUM($D14:D14) -> 0 | E15: =SUM($D14:E14) -> 20 | F15: =SUM($D14:F14) -> 100 | G15: =SUM($D14:G14) -> 100 | H15: =SUM($D14:H14) -> 100 | I15: =SUM($D14:I14) -> 100
A16: 1.2.5.1.2.3 | B16: [M2] C / F2 / OC / DEMSUB / Demoliciones Losa de Fundación F1 | C16: Avance parcial % | D16: =SUM('Avance Diario'!G17:L17) -> 0 | E16: =SUM('Avance Diario'!M17:S17) -> 0 | F16: =SUM('Avance Diario'!T17:Z17) -> 45.454545 | G16: =SUM('Avance Diario'!AA17:AG17) -> 45.454545 | H16: =SUM('Avance Diario'!AH17:AN17) -> 9.0909091 | I16: =SUM('Avance Diario'!AO17:AQ17) -> 0
C17: Avance acumulado % | D17: =SUM($D16:D16) -> 0 | E17: =SUM($D16:E16) -> 0 | F17: =SUM($D16:F16) -> 45.454545 | G17: =SUM($D16:G16) -> 90.909091 | H17: =SUM($D16:H16) -> 100 | I17: =SUM($D16:I16) -> 100
A18: 1.2.5.1.3 | B18: C / F2 / OC / DEMOLICIONES SUBTERRÁNEO CICLO 02 | C18: Avance parcial % | D18: =SUM('Avance Diario'!G19:L19) -> 17.391304 | E18: =SUM('Avance Diario'!M19:S19) -> 21.73913 | F18: =SUM('Avance Diario'!T19:Z19) -> 21.73913 | G18: =SUM('Avance Diario'!AA19:AG19) -> 21.73913 | H18: =SUM('Avance Diario'!AH19:AN19) -> 17.391304 | I18: =SUM('Avance Diario'!AO19:AQ19) -> 0
C19: Avance acumulado % | D19: =SUM($D18:D18) -> 17.391304 | E19: =SUM($D18:E18) -> 39.130435 | F19: =SUM($D18:F18) -> 60.869565 | G19: =SUM($D18:G18) -> 82.608696 | H19: =SUM($D18:H18) -> 100 | I19: =SUM($D18:I18) -> 100
A20: 1.2.5.1.3.6 | B20: [M2] C / F2 / OC / DEMSUB / Demoliciones Cámaras PEAS & Desgrasadora PEAS 1-2 | C20: Avance parcial % | D20: =SUM('Avance Diario'!G21:L21) -> 0 | E20: =SUM('Avance Diario'!M21:S21) -> 0 | F20: =SUM('Avance Diario'!T21:Z21) -> 0 | G20: =SUM('Avance Diario'!AA21:AG21) -> 71.428571 | H20: =SUM('Avance Diario'!AH21:AN21) -> 28.571429 | I20: =SUM('Avance Diario'!AO21:AQ21) -> 0
C21: Avance acumulado % | D21: =SUM($D20:D20) -> 0 | E21: =SUM($D20:E20) -> 0 | F21: =SUM($D20:F20) -> 0 | G21: =SUM($D20:G20) -> 71.428571 | H21: =SUM($D20:H20) -> 100 | I21: =SUM($D20:I20) -> 100
A22: 1.2.5.1.3.2 | B22: [M2] C / F2 / OC / DEMSUB / Demoliciones Cámaras A.LL | C22: Avance parcial % | D22: =SUM('Avance Diario'!G23:L23) -> 0 | E22: =SUM('Avance Diario'!M23:S23) -> 0 | F22: =SUM('Avance Diario'!T23:Z23) -> 0 | G22: =SUM('Avance Diario'!AA23:AG23) -> 100 | H22: =SUM('Avance Diario'!AH23:AN23) -> 0 | I22: =SUM('Avance Diario'!AO23:AQ23) -> 0
C23: Avance acumulado % | D23: =SUM($D22:D22) -> 0 | E23: =SUM($D22:E22) -> 0 | F23: =SUM($D22:F22) -> 0 | G23: =SUM($D22:G22) -> 100 | H23: =SUM($D22:H22) -> 100 | I23: =SUM($D22:I22) -> 100
A24: 1.2.5.1.3.3 | B24: [M2] C / F2 / OC / DEMSUB / Demoliciones Losa de Fundación F4 | C24: Avance parcial % | D24: =SUM('Avance Diario'!G25:L25) -> 44.444444 | E24: =SUM('Avance Diario'!M25:S25) -> 55.555556 | F24: =SUM('Avance Diario'!T25:Z25) -> 0 | G24: =SUM('Avance Diario'!AA25:AG25) -> 0 | H24: =SUM('Avance Diario'!AH25:AN25) -> 0 | I24: =SUM('Avance Diario'!AO25:AQ25) -> 0
C25: Avance acumulado % | D25: =SUM($D24:D24) -> 44.444444 | E25: =SUM($D24:E24) -> 100 | F25: =SUM($D24:F24) -> 100 | G25: =SUM($D24:G24) -> 100 | H25: =SUM($D24:H24) -> 100 | I25: =SUM($D24:I24) -> 100
A26: 1.2.5.1.3.4 | B26: [M2] C / F2 / OC / DEMSUB / Demolición Muros y Losa | C26: Avance parcial % | D26: =SUM('Avance Diario'!G27:L27) -> 0 | E26: =SUM('Avance Diario'!M27:S27) -> 0 | F26: =SUM('Avance Diario'!T27:Z27) -> 55.555556 | G26: =SUM('Avance Diario'!AA27:AG27) -> 44.444444 | H26: =SUM('Avance Diario'!AH27:AN27) -> 0 | I26: =SUM('Avance Diario'!AO27:AQ27) -> 0
C27: Avance acumulado % | D27: =SUM($D26:D26) -> 0 | E27: =SUM($D26:E26) -> 0 | F27: =SUM($D26:F26) -> 55.555556 | G27: =SUM($D26:G26) -> 100 | H27: =SUM($D26:H26) -> 100 | I27: =SUM($D26:I26) -> 100
A28: 1.2.5.1.3.5 | B28: [M2] C / F2 / OC / DEMSUB / Demolición Rampa | C28: Avance parcial % | D28: =SUM('Avance Diario'!G29:L29) -> 0 | E28: =SUM('Avance Diario'!M29:S29) -> 0 | F28: =SUM('Avance Diario'!T29:Z29) -> 0 | G28: =SUM('Avance Diario'!AA29:AG29) -> 20 | H28: =SUM('Avance Diario'!AH29:AN29) -> 80 | I28: =SUM('Avance Diario'!AO29:AQ29) -> 0
C29: Avance acumulado % | D29: =SUM($D28:D28) -> 0 | E29: =SUM($D28:E28) -> 0 | F29: =SUM($D28:F28) -> 0 | G29: =SUM($D28:G28) -> 20 | H29: =SUM($D28:H28) -> 100 | I29: =SUM($D28:I28) -> 100
B30: C / F3 / OC / DEMOLICIONES | C30: Avance parcial % | D30: =SUM('Avance Diario'!G31:L31) -> 0 | E30: =SUM('Avance Diario'!M31:S31) -> 0 | F30: =SUM('Avance Diario'!T31:Z31) -> 27.777778 | G30: =SUM('Avance Diario'!AA31:AG31) -> 27.777778 | H30: =SUM('Avance Diario'!AH31:AN31) -> 27.777778 | I30: =SUM('Avance Diario'!AO31:AQ31) -> 16.666667
C31: Avance acumulado % | D31: =SUM($D30:D30) -> 0 | E31: =SUM($D30:E30) -> 0 | F31: =SUM($D30:F30) -> 27.777778 | G31: =SUM($D30:G30) -> 55.555556 | H31: =SUM($D30:H30) -> 83.333333 | I31: =SUM($D30:I30) -> 100
A32: 1.2.6.1.3 | B32: C / F3 / OC / DEMOLICIONES SUPERFICIE | C32: Avance parcial % | D32: =SUM('Avance Diario'!G33:L33) -> 0 | E32: =SUM('Avance Diario'!M33:S33) -> 0 | F32: =SUM('Avance Diario'!T33:Z33) -> 27.777778 | G32: =SUM('Avance Diario'!AA33:AG33) -> 27.777778 | H32: =SUM('Avance Diario'!AH33:AN33) -> 27.777778 | I32: =SUM('Avance Diario'!AO33:AQ33) -> 16.666667
C33: Avance acumulado % | D33: =SUM($D32:D32) -> 0 | E33: =SUM($D32:E32) -> 0 | F33: =SUM($D32:F32) -> 27.777778 | G33: =SUM($D32:G32) -> 55.555556 | H33: =SUM($D32:H32) -> 83.333333 | I33: =SUM($D32:I32) -> 100
A34: 1.2.6.1.3.1 | B34: [M3] C / F3 / OC / DEMSUP / Demolición Vigas de Borde Losa Existente | C34: Avance parcial % | D34: =SUM('Avance Diario'!G35:L35) -> 0 | E34: =SUM('Avance Diario'!M35:S35) -> 0 | F34: =SUM('Avance Diario'!T35:Z35) -> 62.5 | G34: =SUM('Avance Diario'!AA35:AG35) -> 37.5 | H34: =SUM('Avance Diario'!AH35:AN35) -> 0 | I34: =SUM('Avance Diario'!AO35:AQ35) -> 0
C35: Avance acumulado % | D35: =SUM($D34:D34) -> 0 | E35: =SUM($D34:E34) -> 0 | F35: =SUM($D34:F34) -> 62.5 | G35: =SUM($D34:G34) -> 100 | H35: =SUM($D34:H34) -> 100 | I35: =SUM($D34:I34) -> 100
A36: 1.2.6.1.3.2.1 | B36: [M2] C / F3 / OC / DEMSUP / Demolición veredas | C36: Avance parcial % | D36: =SUM('Avance Diario'!G37:L37) -> 0 | E36: =SUM('Avance Diario'!M37:S37) -> 0 | F36: =SUM('Avance Diario'!T37:Z37) -> 0 | G36: =SUM('Avance Diario'!AA37:AG37) -> 66.666667 | H36: =SUM('Avance Diario'!AH37:AN37) -> 33.333333 | I36: =SUM('Avance Diario'!AO37:AQ37) -> 0
C37: Avance acumulado % | D37: =SUM($D36:D36) -> 0 | E37: =SUM($D36:E36) -> 0 | F37: =SUM($D36:F36) -> 0 | G37: =SUM($D36:G36) -> 66.666667 | H37: =SUM($D36:H36) -> 100 | I37: =SUM($D36:I36) -> 100
A38: 1.2.6.1.3.2.2 | B38: [M2] C / F3 / OC / DEMSUP / Demolición jardinería | C38: Avance parcial % | D38: =SUM('Avance Diario'!G39:L39) -> 0 | E38: =SUM('Avance Diario'!M39:S39) -> 0 | F38: =SUM('Avance Diario'!T39:Z39) -> 0 | G38: =SUM('Avance Diario'!AA39:AG39) -> 66.666667 | H38: =SUM('Avance Diario'!AH39:AN39) -> 33.333333 | I38: =SUM('Avance Diario'!AO39:AQ39) -> 0
C39: Avance acumulado % | D39: =SUM($D38:D38) -> 0 | E39: =SUM($D38:E38) -> 0 | F39: =SUM($D38:F38) -> 0 | G39: =SUM($D38:G38) -> 66.666667 | H39: =SUM($D38:H38) -> 100 | I39: =SUM($D38:I38) -> 100
A40: 1.2.6.1.3.3 | B40: [M2] C / F3 / OC / DEMSUP / Demolición de Losas Existentes para Escaleras | C40: Avance parcial % | D40: =SUM('Avance Diario'!G41:L41) -> 0 | E40: =SUM('Avance Diario'!M41:S41) -> 0 | F40: =SUM('Avance Diario'!T41:Z41) -> 0 | G40: =SUM('Avance Diario'!AA41:AG41) -> 0 | H40: =SUM('Avance Diario'!AH41:AN41) -> 57.142857 | I40: =SUM('Avance Diario'!AO41:AQ41) -> 42.857143
...
