Workbook

Sheet Datos
B1: ITEM | C1: Nombre de tarea | D1: Duración (hábil L-V) | E1: Días Corridos | F1: Comienzo | G1: Fin
B2: 1.2.4.1.7 | C2: C / F1 / OC / FUNDACIONES ESTANQUE & LOSA FUNDACIÓN | D2: 34 días | E2: 50 días | F2: 46335 | G2: 46384
B3: 1.2.4.1.7.1 | C3: C / F1 / OC / FE / CICLO 01 | D3: 9 días | E3: 11 días | F3: 46335 | G3: 46345
B4: 1.2.4.1.7.1.3 | C4: [M3] C / F1 / OC / FE / C1 / Hormigón | D4: 2 días | E4: 2 días | F4: 46344 | G4: 46345
B5: 1.2.4.1.7.2 | C5: C / F1 / OC / FE / CICLO 02 | D5: 11 días | E5: 16 días | F5: 46359 | G5: 46374
B6: 1.2.4.1.7.2.3 | C6: [M3] C / F1 / OC / FE / C2 / Hormigón | D6: 4 días | E6: 4 días | F6: 46371 | G6: 46374
B7: 1.2.4.1.7.3 | C7: C / F1 / OC / FE / CICLO 03 | D7: 11 días | E7: 18 días | F7: 46367 | G7: 46384
B8: 1.2.4.1.7.3.3 | C8: [M3] C / F1 / OC / FE / C3 / Hormigón | D8: 4 días | E8: 7 días | F8: 46378 | G8: 46384
B9: 1.2.4.1.8 | C9: C / F1 / OC / ELEV. MUROS Y PILARES ESTANQUE | D9: 34 días | E9: 53 días | F9: 46346 | G9: 46398
B10: 1.2.4.1.8.1 | C10: C / F1 / OC / Elev / CICLO 01 | D10: 27 días | E10: 41 días | F10: 46346 | G10: 46386
B11: 1.2.4.1.8.1.3 | C11: [M3] C / F1 / OC / Elev / C1 / Hormigón | D11: 2 días | E11: 2 días | F11: 46385 | G11: 46386
B12: 1.2.4.1.8.2 | C12: C / F1 / OC / Elev / CICLO 02 | D12: 10 días | E12: 16 días | F12: 46377 | G12: 46392
B13: 1.2.4.1.8.2.3 | C13: [M3] C / F1 / OC / Elev / C2 / Hormigón | D13: 2 días | E13: 2 días | F13: 46391 | G13: 46392
... B92: 1.2.6.1.11.10 | C92: [M3] C / F3 / OC / RP / AREA COMUN PASILLO Z3 | D92: 5 días | E92: 7 días | F92: 46479 | G92: 46485

Sheet Avance Diario
G1: S04 | H1: S04 | I1: S04 | J1: S04 | K1: S04 | L1: S04 | M1: S04 | N1: S05 | O1: S05 | P1: S05 | Q1: S05 | R1: S05 | S1: S05 | T1: S05 | U1: S06 | V1: S06 | W1: S06 | X1: S06 | Y1: S06 | Z1: S06 | AA1: S06 | AB1: S07 | AC1: S07 | AD1: S07 | AE1: S07 | AF1: S07 | AG1: S07 | AH1: S07 | AI1: S08 | AJ1: S08 | AK1: S08 | AL1: S08 | AM1: S08 | AN1: S08 | AO1: S08 | AP1: S09 | AQ1: S09 | AR1: S09 | AS1: S09 | AT1: S09 | AU1: S09 | AV1: S09 | AW1: S10 | AX1: S10 | AY1: S10 | AZ1: S10 | BA1: S10 | BB1: S10 | BC1: S10 | BD1: S11 | BE1: S11 | BF1: S11 | BG1: S11 | BH1: S11 | BI1: S11 | BJ1: S11 | BK1: S12 | BL1: S12 | BM1: S12 | BN1: S12 | BO1: S12 | BP1: S12 | BQ1: S12 | BR1: S13 | BS1: S13 | BT1: S13 | BU1: S13 | BV1: S13 | BW1: S13 | BX1: S13 | BY1: S14 | BZ1: S14 | CA1: S14 | CB1: S14 | CC1: S14 | CD1: S14 | CE1: S14 | CF1: S15 | CG1: S15 | CH1: S15 | CI1: S15 | CJ1: S15 | CK1: S15 | CL1: S15 | CM1: S16 | CN1: S16 | CO1: S16 | CP1: S16 | CQ1: S16 | CR1: S16 | CS1: S16 | CT1: S17 | CU1: S17 | CV1: S17 | CW1: S17 | CX1: S17 | CY1: S17 | CZ1: S17 | DA1: S18 | DB1: S18 | DC1: S18 | DD1: S18 | DE1: S18 | DF1: S18 | DG1: S18 | DH1: S19 | DI1: S19 | DJ1: S19 | DK1: S19 | DL1: S19 | DM1: S19 | DN1: S19 | DO1: S20 | DP1: S20 | DQ1: S20 | DR1: S20 | DS1: S20 | DT1: S20 | DU1: S20 | DV1: S21 | DW1: S21 | DX1: S21 | DY1: S21 | DZ1: S21 | EA1: S21 | EB1: S21 | EC1: S22 | ED1: S22 | EE1: S22 | EF1: S22 | EG1: S22 | EH1: S22 | EI1: S22 | EJ1: S23 | EK1: S23 | EL1: S23 | EM1: S23 | EN1: S23 | EO1: S23 | EP1: S23 | EQ1: S24 | ER1: S24 | ES1: S24 | ET1: S24 | EU1: S24 | EV1: S24 | EW1: S24 | EX1: S25 | EY1: S25 | EZ1: S25 | FA1: S25 | FB1: S25 | FC1: S25 | FD1: S25 | FE1: S26 | FF1: S26 | FG1: S26 | FH1: S26 | FI1: S26 | FJ1: S26 | FK1: S26 | FL1: S27 | FM1: S27 | FN1: S27 | FO1: S27 | FP1: S27 | FQ1: S27 | FR1: S27 | FS1: S28 | FT1: S28 | FU1: S28 | FV1: S28 | FW1: S28 | FX1: S28 | FY1: S28 | FZ1: S29 | GA1: S29 | GB1: S29 | GC1: S29 | GD1: S29 | GE1: S29 | GF1: S29 | GG1: S30 | GH1: S30 | GI1: S30 | GJ1: S30 | GK1: S30 | GL1: S30 | GM1: S30 | GN1: S31 | GO1: S31 | GP1: S31 | GQ1: S31 | GR1: S31 | GS1: S31 | GT1: S31 | GU1: S32 | GV1: S32 | GW1: S32 | GX1: S32 | GY1: S32 | GZ1: S32 | HA1: S32 | HB1: S33 | HC1: S33 | HD1: S33 | HE1: S33
G2: 46279 | H2: 46280 | I2: 46281 | J2: 46282 | K2: 46283 | L2: 46284 | M2: 46285 | N2: 46286 | O2: 46287 | P2: 46288 | Q2: 46289 | R2: 46290 | S2: 46291 | T2: 46292 | U2: 46293 | V2: 46294 | W2: 46295 | X2: 46296 | Y2: 46297 | Z2: 46298 | AA2: 46299 | AB2: 46300 | AC2: 46301 | AD2: 46302 | AE2: 46303 | AF2: 46304 | AG2: 46305 | AH2: 46306 | AI2: 46307 | AJ2: 46308 | AK2: 46309 | AL2: 46310 | AM2: 46311 | AN2: 46312 | AO2: 46313 | AP2: 46314 | AQ2: 46315 | AR2: 46316 | AS2: 46317 | AT2: 46318 | AU2: 46319 | AV2: 46320 | AW2: 46321 | AX2: 46322 | AY2: 46323 | AZ2: 46324 | BA2: 46325 | BB2: 46326 | BC2: 46327 | BD2: 46328 | BE2: 46329 | BF2: 46330 | BG2: 46331 | BH2: 46332 | BI2: 46333 | BJ2: 46334 | BK2: 46335 | BL2: 46336 | BM2: 46337 | BN2: 46338 | BO2: 46339 | BP2: 46340 | BQ2: 46341 | BR2: 46342 | BS2: 46343 | BT2: 46344 | BU2: 46345 | BV2: 46346 | BW2: 46347 | BX2: 46348 | BY2: 46349 | BZ2: 46350 | CA2: 46351 | CB2: 46352 | CC2: 46353 | CD2: 46354 | CE2: 46355 | CF2: 46356 | CG2: 46357 | CH2: 46358 | CI2: 46359 | CJ2: 46360 | CK2: 46361 | CL2: 46362 | CM2: 46363 | CN2: 46364 | CO2: 46365 | CP2: 46366 | CQ2: 46367 | CR2: 46368 | CS2: 46369 | CT2: 46370 | CU2: 46371 | CV2: 46372 | CW2: 46373 | CX2: 46374 | CY2: 46375 | CZ2: 46376 | DA2: 46377 | DB2: 46378 | DC2: 46379 | DD2: 46380 | DE2: 46381 | DF2: 46382 | DG2: 46383 | DH2: 46384 | DI2: 46385 | DJ2: 46386 | DK2: 46387 | DL2: 46388 | DM2: 46389 | DN2: 46390 | DO2: 46391 | DP2: 46392 | DQ2: 46393 | DR2: 46394 | DS2: 46395 | DT2: 46396 | DU2: 46397 | DV2: 46398 | DW2: 46399 | DX2: 46400 | DY2: 46401 | DZ2: 46402 | EA2: 46403 | EB2: 46404 | EC2: 46405 | ED2: 46406 | EE2: 46407 | EF2: 46408 | EG2: 46409 | EH2: 46410 | EI2: 46411 | EJ2: 46412 | EK2: 46413 | EL2: 46414 | EM2: 46415 | EN2: 46416 | EO2: 46417 | EP2: 46418 | EQ2: 46419 | ER2: 46420 | ES2: 46421 | ET2: 46422 | EU2: 46423 | EV2: 46424 | EW2: 46425 | EX2: 46426 | EY2: 46427 | EZ2: 46428 | FA2: 46429 | FB2: 46430 | FC2: 46431 | FD2: 46432 | FE2: 46433 | FF2: 46434 | FG2: 46435 | FH2: 46436 | FI2: 46437 | FJ2: 46438 | FK2: 46439 | FL2: 46440 | FM2: 46441 | FN2: 46442 | FO2: 46443 | FP2: 46444 | FQ2: 46445 | FR2: 46446 | FS2: 46447 | FT2: 46448 | FU2: 46449 | FV2: 46450 | FW2: 46451 | FX2: 46452 | FY2: 46453 | FZ2: 46454 | GA2: 46455 | GB2: 46456 | GC2: 46457 | GD2: 46458 | GE2: 46459 | GF2: 46460 | GG2: 46461 | GH2: 46462 | GI2: 46463 | GJ2: 46464 | GK2: 46465 | GL2: 46466 | GM2: 46467 | GN2: 46468 | GO2: 46469 | GP2: 46470 | GQ2: 46471 | GR2: 46472 | GS2: 46473 | GT2: 46474 | GU2: 46475 | GV2: 46476 | GW2: 46477 | GX2: 46478 | GY2: 46479 | GZ2: 46480 | HA2: 46481 | HB2: 46482 | HC2: 46483 | HD2: 46484 | HE2: 46485
A3: 1.2.4.1.7 | B3: C / F1 / OC / FUNDACIONES ESTANQUE & LOSA FUNDACIÓN | C3: =Datos!F2 -> 46335 | D3: =Datos!G2 -> 46384 | E3: =NETWORKDAYS(C3,D3) -> 36 | F3: Avance parcial % | G3: =IF(AND(G$2>=$C3,G$2<=$D3,WEEKDAY(G$2,2)<=5),100/$E3,0) -> 0 | H3: =IF(AND(H$2>=$C3,H$2<=$D3,WEEKDAY(H$2,2)<=5),100/$E3,0) -> 0 | I3: =IF(AND(I$2>=$C3,I$2<=$D3,WEEKDAY(I$2,2)<=5),100/$E3,0) -> 0 | J3: =IF(AND(J$2>=$C3,J$2<=$D3,WEEKDAY(J$2,2)<=5),100/$E3,0) -> 0 | K3: =IF(AND(K$2>=$C3,K$2<=$D3,WEEKDAY(K$2,2)<=5),100/$E3,0) -> 0 | L3: =IF(AND(L$2>=$C3,L$2<=$D3,WEEKDAY(L$2,2)<=5),100/$E3,0) -> 0 | M3: =IF(AND(M$2>=$C3,M$2<=$D3,WEEKDAY(M$2,2)<=5),100/$E3,0) -> 0 | N3: =IF(AND(N$2>=$C3,N$2<=$D3,WEEKDAY(N$2,2)<=5),100/$E3,0) -> 0 | ... HE3: =IF(AND(HE$2>=$C3,HE$2<=$D3,WEEKDAY(HE$2,2)<=5),100/$E3,0) -> 0
F4: Avance acumulado % | G4: =SUM($G3:G3) -> 0 | H4: =SUM($G3:H3) -> 0 | I4: =SUM($G3:I3) -> 0 | J4: =SUM($G3:J3) -> 0 | K4: =SUM($G3:K3) -> 0 | L4: =SUM($G3:L3) -> 0 | M4: =SUM($G3:M3) -> 0 | N4: =SUM($G3:N3) -> 0 | ... HE4: =SUM($G3:HE3) -> 100
A5: 1.2.4.1.7.1 | B5: C / F1 / OC / FE / CICLO 01 | C5: =Datos!F3 -> 46335 | D5: =Datos!G3 -> 46345 | E5: =NETWORKDAYS(C5,D5) -> 9 | F5: Avance parcial % | G5: =IF(AND(G$2>=$C5,G$2<=$D5,WEEKDAY(G$2,2)<=5),100/$E5,0) -> 0 | H5: =IF(AND(H$2>=$C5,H$2<=$D5,WEEKDAY(H$2,2)<=5),100/$E5,0) -> 0 | I5: =IF(AND(I$2>=$C5,I$2<=$D5,WEEKDAY(I$2,2)<=5),100/$E5,0) -> 0 | J5: =IF(AND(J$2>=$C5,J$2<=$D5,WEEKDAY(J$2,2)<=5),100/$E5,0) -> 0 | K5: =IF(AND(K$2>=$C5,K$2<=$D5,WEEKDAY(K$2,2)<=5),100/$E5,0) -> 0 | L5: =IF(AND(L$2>=$C5,L$2<=$D5,WEEKDAY(L$2,2)<=5),100/$E5,0) -> 0 | M5: =IF(AND(M$2>=$C5,M$2<=$D5,WEEKDAY(M$2,2)<=5),100/$E5,0) -> 0 | N5: =IF(AND(N$2>=$C5,N$2<=$D5,WEEKDAY(N$2,2)<=5),100/$E5,0) -> 0 | ... HE5: =IF(AND(HE$2>=$C5,HE$2<=$D5,WEEKDAY(HE$2,2)<=5),100/$E5,0) -> 0
F6: Avance acumulado % | G6: =SUM($G5:G5) -> 0 | H6: =SUM($G5:H5) -> 0 | I6: =SUM($G5:I5) -> 0 | J6: =SUM($G5:J5) -> 0 | K6: =SUM($G5:K5) -> 0 | L6: =SUM($G5:L5) -> 0 | M6: =SUM($G5:M5) -> 0 | N6: =SUM($G5:N5) -> 0 | ... HE6: =SUM($G5:HE5) -> 100
A7: 1.2.4.1.7.1.3 | B7: [M3] C / F1 / OC / FE / C1 / Hormigón | C7: =Datos!F4 -> 46344 | D7: =Datos!G4 -> 46345 | E7: =NETWORKDAYS(C7,D7) -> 2 | F7: Avance parcial % | G7: =IF(AND(G$2>=$C7,G$2<=$D7,WEEKDAY(G$2,2)<=5),100/$E7,0) -> 0 | H7: =IF(AND(H$2>=$C7,H$2<=$D7,WEEKDAY(H$2,2)<=5),100/$E7,0) -> 0 | I7: =IF(AND(I$2>=$C7,I$2<=$D7,WEEKDAY(I$2,2)<=5),100/$E7,0) -> 0 | J7: =IF(AND(J$2>=$C7,J$2<=$D7,WEEKDAY(J$2,2)<=5),100/$E7,0) -> 0 | K7: =IF(AND(K$2>=$C7,K$2<=$D7,WEEKDAY(K$2,2)<=5),100/$E7,0) -> 0 | L7: =IF(AND(L$2>=$C7,L$2<=$D7,WEEKDAY(L$2,2)<=5),100/$E7,0) -> 0 | M7: =IF(AND(M$2>=$C7,M$2<=$D7,WEEKDAY(M$2,2)<=5),100/$E7,0) -> 0 | N7: =IF(AND(N$2>=$C7,N$2<=$D7,WEEKDAY(N$2,2)<=5),100/$E7,0) -> 0 | ... HE7: =IF(AND(HE$2>=$C7,HE$2<=$D7,WEEKDAY(HE$2,2)<=5),100/$E7,0) -> 0
F8: Avance acumulado % | G8: =SUM($G7:G7) -> 0 | H8: =SUM($G7:H7) -> 0 | I8: =SUM($G7:I7) -> 0 | J8: =SUM($G7:J7) -> 0 | K8: =SUM($G7:K7) -> 0 | L8: =SUM($G7:L7) -> 0 | M8: =SUM($G7:M7) -> 0 | N8: =SUM($G7:N7) -> 0 | ... HE8: =SUM($G7:HE7) -> 100
A9: 1.2.4.1.7.2 | B9: C / F1 / OC / FE / CICLO 02 | C9: =Datos!F5 -> 46359 | D9: =Datos!G5 -> 46374 | E9: =NETWORKDAYS(C9,D9) -> 12 | F9: Avance parcial % | G9: =IF(AND(G$2>=$C9,G$2<=$D9,WEEKDAY(G$2,2)<=5),100/$E9,0) -> 0 | H9: =IF(AND(H$2>=$C9,H$2<=$D9,WEEKDAY(H$2,2)<=5),100/$E9,0) -> 0 | I9: =IF(AND(I$2>=$C9,I$2<=$D9,WEEKDAY(I$2,2)<=5),100/$E9,0) -> 0 | J9: =IF(AND(J$2>=$C9,J$2<=$D9,WEEKDAY(J$2,2)<=5),100/$E9,0) -> 0 | K9: =IF(AND(K$2>=$C9,K$2<=$D9,WEEKDAY(K$2,2)<=5),100/$E9,0) -> 0 | L9: =IF(AND(L$2>=$C9,L$2<=$D9,WEEKDAY(L$2,2)<=5),100/$E9,0) -> 0 | M9: =IF(AND(M$2>=$C9,M$2<=$D9,WEEKDAY(M$2,2)<=5),100/$E9,0) -> 0 | N9: =IF(AND(N$2>=$C9,N$2<=$D9,WEEKDAY(N$2,2)<=5),100/$E9,0) -> 0 | ... HE9: =IF(AND(HE$2>=$C9,HE$2<=$D9,WEEKDAY(HE$2,2)<=5),100/$E9,0) -> 0
F10: Avance acumulado % | G10: =SUM($G9:G9) -> 0 | H10: =SUM($G9:H9) -> 0 | I10: =SUM($G9:I9) -> 0 | J10: =SUM($G9:J9) -> 0 | K10: =SUM($G9:K9) -> 0 | L10: =SUM($G9:L9) -> 0 | M10: =SUM($G9:M9) -> 0 | N10: =SUM($G9:N9) -> 0 | ... HE10: =SUM($G9:HE9) -> 100
A11: 1.2.4.1.7.2.3 | B11: [M3] C / F1 / OC / FE / C2 / Hormigón | C11: =Datos!F6 -> 46371 | D11: =Datos!G6 -> 46374 | E11: =NETWORKDAYS(C11,D11) -> 4 | F11: Avance parcial % | G11: =IF(AND(G$2>=$C11,G$2<=$D11,WEEKDAY(G$2,2)<=5),100/$E11,0) -> 0 | H11: =IF(AND(H$2>=$C11,H$2<=$D11,WEEKDAY(H$2,2)<=5),100/$E11,0) -> 0 | I11: =IF(AND(I$2>=$C11,I$2<=$D11,WEEKDAY(I$2,2)<=5),100/$E11,0) -> 0 | J11: =IF(AND(J$2>=$C11,J$2<=$D11,WEEKDAY(J$2,2)<=5),100/$E11,0) -> 0 | K11: =IF(AND(K$2>=$C11,K$2<=$D11,WEEKDAY(K$2,2)<=5),100/$E11,0) -> 0 | L11: =IF(AND(L$2>=$C11,L$2<=$D11,WEEKDAY(L$2,2)<=5),100/$E11,0) -> 0 | M11: =IF(AND(M$2>=$C11,M$2<=$D11,WEEKDAY(M$2,2)<=5),100/$E11,0) -> 0 | N11: =IF(AND(N$2>=$C11,N$2<=$D11,WEEKDAY(N$2,2)<=5),100/$E11,0) -> 0 | ... HE11: =IF(AND(HE$2>=$C11,HE$2<=$D11,WEEKDAY(HE$2,2)<=5),100/$E11,0) -> 0
F12: Avance acumulado % | G12: =SUM($G11:G11) -> 0 | H12: =SUM($G11:H11) -> 0 | I12: =SUM($G11:I11) -> 0 | J12: =SUM($G11:J11) -> 0 | K12: =SUM($G11:K11) -> 0 | L12: =SUM($G11:L11) -> 0 | M12: =SUM($G11:M11) -> 0 | N12: =SUM($G11:N11) -> 0 | ... HE12: =SUM($G11:HE11) -> 100
A13: 1.2.4.1.7.3 | B13: C / F1 / OC / FE / CICLO 03 | C13: =Datos!F7 -> 46367 | D13: =Datos!G7 -> 46384 | E13: =NETWORKDAYS(C13,D13) -> 12 | F13: Avance parcial % | G13: =IF(AND(G$2>=$C13,G$2<=$D13,WEEKDAY(G$2,2)<=5),100/$E13,0) -> 0 | H13: =IF(AND(H$2>=$C13,H$2<=$D13,WEEKDAY(H$2,2)<=5),100/$E13,0) -> 0 | I13: =IF(AND(I$2>=$C13,I$2<=$D13,WEEKDAY(I$2,2)<=5),100/$E13,0) -> 0 | J13: =IF(AND(J$2>=$C13,J$2<=$D13,WEEKDAY(J$2,2)<=5),100/$E13,0) -> 0 | K13: =IF(AND(K$2>=$C13,K$2<=$D13,WEEKDAY(K$2,2)<=5),100/$E13,0) -> 0 | L13: =IF(AND(L$2>=$C13,L$2<=$D13,WEEKDAY(L$2,2)<=5),100/$E13,0) -> 0 | M13: =IF(AND(M$2>=$C13,M$2<=$D13,WEEKDAY(M$2,2)<=5),100/$E13,0) -> 0 | N13: =IF(AND(N$2>=$C13,N$2<=$D13,WEEKDAY(N$2,2)<=5),100/$E13,0) -> 0 | ... HE13: =IF(AND(HE$2>=$C13,HE$2<=$D13,WEEKDAY(HE$2,2)<=5),100/$E13,0) -> 0
F14: Avance acumulado % | G14: =SUM($G13:G13) -> 0 | H14: =SUM($G13:H13) -> 0 | I14: =SUM($G13:I13) -> 0 | J14: =SUM($G13:J13) -> 0 | K14: =SUM($G13:K13) -> 0 | L14: =SUM($G13:L13) -> 0 | M14: =SUM($G13:M13) -> 0 | N14: =SUM($G13:N13) -> 0 | ... HE14: =SUM($G13:HE13) -> 100
A15: 1.2.4.1.7.3.3 | B15: [M3] C / F1 / OC / FE / C3 / Hormigón | C15: =Datos!F8 -> 46378 | D15: =Datos!G8 -> 46384 | E15: =NETWORKDAYS(C15,D15) -> 5 | F15: Avance parcial % | G15: =IF(AND(G$2>=$C15,G$2<=$D15,WEEKDAY(G$2,2)<=5),100/$E15,0) -> 0 | H15: =IF(AND(H$2>=$C15,H$2<=$D15,WEEKDAY(H$2,2)<=5),100/$E15,0) -> 0 | I15: =IF(AND(I$2>=$C15,I$2<=$D15,WEEKDAY(I$2,2)<=5),100/$E15,0) -> 0 | J15: =IF(AND(J$2>=$C15,J$2<=$D15,WEEKDAY(J$2,2)<=5),100/$E15,0) -> 0 | K15: =IF(AND(K$2>=$C15,K$2<=$D15,WEEKDAY(K$2,2)<=5),100/$E15,0) -> 0 | L15: =IF(AND(L$2>=$C15,L$2<=$D15,WEEKDAY(L$2,2)<=5),100/$E15,0) -> 0 | M15: =IF(AND(M$2>=$C15,M$2<=$D15,WEEKDAY(M$2,2)<=5),100/$E15,0) -> 0 | N15: =IF(AND(N$2>=$C15,N$2<=$D15,WEEKDAY(N$2,2)<=5),100/$E15,0) -> 0 | ... HE15: =IF(AND(HE$2>=$C15,HE$2<=$D15,WEEKDAY(HE$2,2)<=5),100/$E15,0) -> 0
F16: Avance acumulado % | G16: =SUM($G15:G15) -> 0 | H16: =SUM($G15:H15) -> 0 | I16: =SUM($G15:I15) -> 0 | J16: =SUM($G15:J15) -> 0 | K16: =SUM($G15:K15) -> 0 | L16: =SUM($G15:L15) -> 0 | M16: =SUM($G15:M15) -> 0 | N16: =SUM($G15:N15) -> 0 | ... HE16: =SUM($G15:HE15) -> 100
A17: 1.2.4.1.8 | B17: C / F1 / OC / ELEV. MUROS Y PILARES ESTANQUE | C17: =Datos!F9 -> 46346 | D17: =Datos!G9 -> 46398 | E17: =NETWORKDAYS(C17,D17) -> 37 | F17: Avance parcial % | G17: =IF(AND(G$2>=$C17,G$2<=$D17,WEEKDAY(G$2,2)<=5),100/$E17,0) -> 0 | H17: =IF(AND(H$2>=$C17,H$2<=$D17,WEEKDAY(H$2,2)<=5),100/$E17,0) -> 0 | I17: =IF(AND(I$2>=$C17,I$2<=$D17,WEEKDAY(I$2,2)<=5),100/$E17,0) -> 0 | J17: =IF(AND(J$2>=$C17,J$2<=$D17,WEEKDAY(J$2,2)<=5),100/$E17,0) -> 0 | K17: =IF(AND(K$2>=$C17,K$2<=$D17,WEEKDAY(K$2,2)<=5),100/$E17,0) -> 0 | L17: =IF(AND(L$2>=$C17,L$2<=$D17,WEEKDAY(L$2,2)<=5),100/$E17,0) -> 0 | M17: =IF(AND(M$2>=$C17,M$2<=$D17,WEEKDAY(M$2,2)<=5),100/$E17,0) -> 0 | N17: =IF(AND(N$2>=$C17,N$2<=$D17,WEEKDAY(N$2,2)<=5),100/$E17,0) -> 0 | ... HE17: =IF(AND(HE$2>=$C17,HE$2<=$D17,WEEKDAY(HE$2,2)<=5),100/$E17,0) -> 0
F18: Avance acumulado % | G18: =SUM($G17:G17) -> 0 | H18: =SUM($G17:H17) -> 0 | I18: =SUM($G17:I17) -> 0 | J18: =SUM($G17:J17) -> 0 | K18: =SUM($G17:K17) -> 0 | L18: =SUM($G17:L17) -> 0 | M18: =SUM($G17:M17) -> 0 | N18: =SUM($G17:N17) -> 0 | ... HE18: =SUM($G17:HE17) -> 100
A19: 1.2.4.1.8.1 | B19: C / F1 / OC / Elev / CICLO 01 | C19: =Datos!F10 -> 46346 | D19: =Datos!G10 -> 46386 | E19: =NETWORKDAYS(C19,D19) -> 29 | F19: Avance parcial % | G19: =IF(AND(G$2>=$C19,G$2<=$D19,WEEKDAY(G$2,2)<=5),100/$E19,0) -> 0 | H19: =IF(AND(H$2>=$C19,H$2<=$D19,WEEKDAY(H$2,2)<=5),100/$E19,0) -> 0 | I19: =IF(AND(I$2>=$C19,I$2<=$D19,WEEKDAY(I$2,2)<=5),100/$E19,0) -> 0 | J19: =IF(AND(J$2>=$C19,J$2<=$D19,WEEKDAY(J$2,2)<=5),100/$E19,0) -> 0 | K19: =IF(AND(K$2>=$C19,K$2<=$D19,WEEKDAY(K$2,2)<=5),100/$E19,0) -> 0 | L19: =IF(AND(L$2>=$C19,L$2<=$D19,WEEKDAY(L$2,2)<=5),100/$E19,0) -> 0 | M19: =IF(AND(M$2>=$C19,M$2<=$D19,WEEKDAY(M$2,2)<=5),100/$E19,0) -> 0 | N19: =IF(AND(N$2>=$C19,N$2<=$D19,WEEKDAY(N$2,2)<=5),100/$E19,0) -> 0 | ... HE19: =IF(AND(HE$2>=$C19,HE$2<=$D19,WEEKDAY(HE$2,2)<=5),100/$E19,0) -> 0
F20: Avance acumulado % | G20: =SUM($G19:G19) -> 0 | H20: =SUM($G19:H19) -> 0 | I20: =SUM($G19:I19) -> 0 | J20: =SUM($G19:J19) -> 0 | K20: =SUM($G19:K19) -> 0 | L20: =SUM($G19:L19) -> 0 | M20: =SUM($G19:M19) -> 0 | N20: =SUM($G19:N19) -> 0 | ... HE20: =SUM($G19:HE19) -> 100
A21: 1.2.4.1.8.1.3 | B21: [M3] C / F1 / OC / Elev / C1 / Hormigón | C21: =Datos!F11 -> 46385 | D21: =Datos!G11 -> 46386 | E21: =NETWORKDAYS(C21,D21) -> 2 | F21: Avance parcial % | G21: =IF(AND(G$2>=$C21,G$2<=$D21,WEEKDAY(G$2,2)<=5),100/$E21,0) -> 0 | H21: =IF(AND(H$2>=$C21,H$2<=$D21,WEEKDAY(H$2,2)<=5),100/$E21,0) -> 0 | I21: =IF(AND(I$2>=$C21,I$2<=$D21,WEEKDAY(I$2,2)<=5),100/$E21,0) -> 0 | J21: =IF(AND(J$2>=$C21,J$2<=$D21,WEEKDAY(J$2,2)<=5),100/$E21,0) -> 0 | K21: =IF(AND(K$2>=$C21,K$2<=$D21,WEEKDAY(K$2,2)<=5),100/$E21,0) -> 0 | L21: =IF(AND(L$2>=$C21,L$2<=$D21,WEEKDAY(L$2,2)<=5),100/$E21,0) -> 0 | M21: =IF(AND(M$2>=$C21,M$2<=$D21,WEEKDAY(M$2,2)<=5),100/$E21,0) -> 0 | N21: =IF(AND(N$2>=$C21,N$2<=$D21,WEEKDAY(N$2,2)<=5),100/$E21,0) -> 0 | ... HE21: =IF(AND(HE$2>=$C21,HE$2<=$D21,WEEKDAY(HE$2,2)<=5),100/$E21,0) -> 0
F22: Avance acumulado % | G22: =SUM($G21:G21) -> 0 | H22: =SUM($G21:H21) -> 0 | I22: =SUM($G21:I21) -> 0 | J22: =SUM($G21:J21) -> 0 | K22: =SUM($G21:K21) -> 0 | L22: =SUM($G21:L21) -> 0 | M22: =SUM($G21:M21) -> 0 | N22: =SUM($G21:N21) -> 0 | ... HE22: =SUM($G21:HE21) -> 100
A23: 1.2.4.1.8.2 | B23: C / F1 / OC / Elev / CICLO 02 | C23: =Datos!F12 -> 46377 | D23: =Datos!G12 -> 46392 | E23: =NETWORKDAYS(C23,D23) -> 12 | F23: Avance parcial % | G23: =IF(AND(G$2>=$C23,G$2<=$D23,WEEKDAY(G$2,2)<=5),100/$E23,0) -> 0 | H23: =IF(AND(H$2>=$C23,H$2<=$D23,WEEKDAY(H$2,2)<=5),100/$E23,0) -> 0 | I23: =IF(AND(I$2>=$C23,I$2<=$D23,WEEKDAY(I$2,2)<=5),100/$E23,0) -> 0 | J23: =IF(AND(J$2>=$C23,J$2<=$D23,WEEKDAY(J$2,2)<=5),100/$E23,0) -> 0 | K23: =IF(AND(K$2>=$C23,K$2<=$D23,WEEKDAY(K$2,2)<=5),100/$E23,0) -> 0 | L23: =IF(AND(L$2>=$C23,L$2<=$D23,WEEKDAY(L$2,2)<=5),100/$E23,0) -> 0 | M23: =IF(AND(M$2>=$C23,M$2<=$D23,WEEKDAY(M$2,2)<=5),100/$E23,0) -> 0 | N23: =IF(AND(N$2>=$C23,N$2<=$D23,WEEKDAY(N$2,2)<=5),100/$E23,0) -> 0 | ... HE23: =IF(AND(HE$2>=$C23,HE$2<=$D23,WEEKDAY(HE$2,2)<=5),100/$E23,0) -> 0
F24: Avance acumulado % | G24: =SUM($G23:G23) -> 0 | H24: =SUM($G23:H23) -> 0 | I24: =SUM($G23:I23) -> 0 | J24: =SUM($G23:J23) -> 0 | K24: =SUM($G23:K23) -> 0 | L24: =SUM($G23:L23) -> 0 | M24: =SUM($G23:M23) -> 0 | N24: =SUM($G23:N23) -> 0 | ... HE24: =SUM($G23:HE23) -> 100
A25: 1.2.4.1.8.2.3 | B25: [M3] C / F1 / OC / Elev / C2 / Hormigón | C25: =Datos!F13 -> 46391 | D25: =Datos!G13 -> 46392 | E25: =NETWORKDAYS(C25,D25) -> 2 | F25: Avance parcial % | G25: =IF(AND(G$2>=$C25,G$2<=$D25,WEEKDAY(G$2,2)<=5),100/$E25,0) -> 0 | H25: =IF(AND(H$2>=$C25,H$2<=$D25,WEEKDAY(H$2,2)<=5),100/$E25,0) -> 0 | I25: =IF(AND(I$2>=$C25,I$2<=$D25,WEEKDAY(I$2,2)<=5),100/$E25,0) -> 0 | J25: =IF(AND(J$2>=$C25,J$2<=$D25,WEEKDAY(J$2,2)<=5),100/$E25,0) -> 0 | K25: =IF(AND(K$2>=$C25,K$2<=$D25,WEEKDAY(K$2,2)<=5),100/$E25,0) -> 0 | L25: =IF(AND(L$2>=$C25,L$2<=$D25,WEEKDAY(L$2,2)<=5),100/$E25,0) -> 0 | M25: =IF(AND(M$2>=$C25,M$2<=$D25,WEEKDAY(M$2,2)<=5),100/$E25,0) -> 0 | N25: =IF(AND(N$2>=$C25,N$2<=$D25,WEEKDAY(N$2,2)<=5),100/$E25,0) -> 0 | ... HE25: =IF(AND(HE$2>=$C25,HE$2<=$D25,WEEKDAY(HE$2,2)<=5),100/$E25,0) -> 0
F26: Avance acumulado % | G26: =SUM($G25:G25) -> 0 | H26: =SUM($G25:H25) -> 0 | I26: =SUM($G25:I25) -> 0 | J26: =SUM($G25:J25) -> 0 | K26: =SUM($G25:K25) -> 0 | L26: =SUM($G25:L25) -> 0 | M26: =SUM($G25:M25) -> 0 | N26: =SUM($G25:N25) -> 0 | ... HE26: =SUM($G25:HE25) -> 100
A27: 1.2.4.1.8.3 | B27: C / F1 / OC / Elev / CICLO 03 | C27: =Datos!F14 -> 46385 | D27: =Datos!G14 -> 46398 | E27: =NETWORKDAYS(C27,D27) -> 10 | F27: Avance parcial % | G27: =IF(AND(G$2>=$C27,G$2<=$D27,WEEKDAY(G$2,2)<=5),100/$E27,0) -> 0 | H27: =IF(AND(H$2>=$C27,H$2<=$D27,WEEKDAY(H$2,2)<=5),100/$E27,0) -> 0 | I27: =IF(AND(I$2>=$C27,I$2<=$D27,WEEKDAY(I$2,2)<=5),100/$E27,0) -> 0 | J27: =IF(AND(J$2>=$C27,J$2<=$D27,WEEKDAY(J$2,2)<=5),100/$E27,0) -> 0 | K27: =IF(AND(K$2>=$C27,K$2<=$D27,WEEKDAY(K$2,2)<=5),100/$E27,0) -> 0 | L27: =IF(AND(L$2>=$C27,L$2<=$D27,WEEKDAY(L$2,2)<=5),100/$E27,0) -> 0 | M27: =IF(AND(M$2>=$C27,M$2<=$D27,WEEKDAY(M$2,2)<=5),100/$E27,0) -> 0 | N27: =IF(AND(N$2>=$C27,N$2<=$D27,WEEKDAY(N$2,2)<=5),100/$E27,0) -> 0 | ... HE27: =IF(AND(HE$2>=$C27,HE$2<=$D27,WEEKDAY(HE$2,2)<=5),100/$E27,0) -> 0
F28: Avance acumulado % | G28: =SUM($G27:G27) -> 0 | H28: =SUM($G27:H27) -> 0 | I28: =SUM($G27:I27) -> 0 | J28: =SUM($G27:J27) -> 0 | K28: =SUM($G27:K27) -> 0 | L28: =SUM($G27:L27) -> 0 | M28: =SUM($G27:M27) -> 0 | N28: =SUM($G27:N27) -> 0 | ... HE28: =SUM($G27:HE27) -> 100
A29: 1.2.4.1.8.3.3 | B29: [M3] C / F1 / OC / Elev / C3 / Hormigón | C29: =Datos!F15 -> 46395 | D29: =Datos!G15 -> 46398 | E29: =NETWORKDAYS(C29,D29) -> 2 | F29: Avance parcial % | G29: =IF(AND(G$2>=$C29,G$2<=$D29,WEEKDAY(G$2,2)<=5),100/$E29,0) -> 0 | H29: =IF(AND(H$2>=$C29,H$2<=$D29,WEEKDAY(H$2,2)<=5),100/$E29,0) -> 0 | I29: =IF(AND(I$2>=$C29,I$2<=$D29,WEEKDAY(I$2,2)<=5),100/$E29,0) -> 0 | J29: =IF(AND(J$2>=$C29,J$2<=$D29,WEEKDAY(J$2,2)<=5),100/$E29,0) -> 0 | K29: =IF(AND(K$2>=$C29,K$2<=$D29,WEEKDAY(K$2,2)<=5),100/$E29,0) -> 0 | L29: =IF(AND(L$2>=$C29,L$2<=$D29,WEEKDAY(L$2,2)<=5),100/$E29,0) -> 0 | M29: =IF(AND(M$2>=$C29,M$2<=$D29,WEEKDAY(M$2,2)<=5),100/$E29,0) -> 0 | N29: =IF(AND(N$2>=$C29,N$2<=$D29,WEEKDAY(N$2,2)<=5),100/$E29,0) -> 0 | ... HE29: =IF(AND(HE$2>=$C29,HE$2<=$D29,WEEKDAY(HE$2,2)<=5),100/$E29,0) -> 0
F30: Avance acumulado % | G30: =SUM($G29:G29) -> 0 | H30: =SUM($G29:H29) -> 0 | I30: =SUM($G29:I29) -> 0 | J30: =SUM($G29:J29) -> 0 | K30: =SUM($G29:K29) -> 0 | L30: =SUM($G29:L29) -> 0 | M30: =SUM($G29:M29) -> 0 | N30: =SUM($G29:N29) -> 0 | ... HE30: =SUM($G29:HE29) -> 100
A31: 1.2.4.1.9 | B31: C / F1 / OC / LOSA SUP. ESTANQUE | C31: =Datos!F16 -> 46393 | D31: =Datos!G16 -> 46422 | E31: =NETWORKDAYS(C31,D31) -> 22 | F31: Avance parcial % | G31: =IF(AND(G$2>=$C31,G$2<=$D31,WEEKDAY(G$2,2)<=5),100/$E31,0) -> 0 | H31: =IF(AND(H$2>=$C31,H$2<=$D31,WEEKDAY(H$2,2)<=5),100/$E31,0) -> 0 | I31: =IF(AND(I$2>=$C31,I$2<=$D31,WEEKDAY(I$2,2)<=5),100/$E31,0) -> 0 | J31: =IF(AND(J$2>=$C31,J$2<=$D31,WEEKDAY(J$2,2)<=5),100/$E31,0) -> 0 | K31: =IF(AND(K$2>=$C31,K$2<=$D31,WEEKDAY(K$2,2)<=5),100/$E31,0) -> 0 | L31: =IF(AND(L$2>=$C31,L$2<=$D31,WEEKDAY(L$2,2)<=5),100/$E31,0) -> 0 | M31: =IF(AND(M$2>=$C31,M$2<=$D31,WEEKDAY(M$2,2)<=5),100/$E31,0) -> 0 | N31: =IF(AND(N$2>=$C31,N$2<=$D31,WEEKDAY(N$2,2)<=5),100/$E31,0) -> 0 | ... HE31: =IF(AND(HE$2>=$C31,HE$2<=$D31,WEEKDAY(HE$2,2)<=5),100/$E31,0) -> 0
F32: Avance acumulado % | G32: =SUM($G31:G31) -> 0 | H32: =SUM($G31:H31) -> 0 | I32: =SUM($G31:I31) -> 0 | J32: =SUM($G31:J31) -> 0 | K32: =SUM($G31:K31) -> 0 | L32: =SUM($G31:L31) -> 0 | M32: =SUM($G31:M31) -> 0 | N32: =SUM($G31:N31) -> 0 | ... HE32: =SUM($G31:HE31) -> 100
A33: 1.2.4.1.9.1 | B33: C / F1 / OC / Losa / CICLO 01 | C33: =Datos!F17 -> 46393 | D33: =Datos!G17 -> 46406 | E33: =NETWORKDAYS(C33,D33) -> 10 | F33: Avance parcial % | G33: =IF(AND(G$2>=$C33,G$2<=$D33,WEEKDAY(G$2,2)<=5),100/$E33,0) -> 0 | H33: =IF(AND(H$2>=$C33,H$2<=$D33,WEEKDAY(H$2,2)<=5),100/$E33,0) -> 0 | I33: =IF(AND(I$2>=$C33,I$2<=$D33,WEEKDAY(I$2,2)<=5),100/$E33,0) -> 0 | J33: =IF(AND(J$2>=$C33,J$2<=$D33,WEEKDAY(J$2,2)<=5),100/$E33,0) -> 0 | K33: =IF(AND(K$2>=$C33,K$2<=$D33,WEEKDAY(K$2,2)<=5),100/$E33,0) -> 0 | L33: =IF(AND(L$2>=$C33,L$2<=$D33,WEEKDAY(L$2,2)<=5),100/$E33,0) -> 0 | M33: =IF(AND(M$2>=$C33,M$2<=$D33,WEEKDAY(M$2,2)<=5),100/$E33,0) -> 0 | N33: =IF(AND(N$2>=$C33,N$2<=$D33,WEEKDAY(N$2,2)<=5),100/$E33,0) -> 0 | ... HE33: =IF(AND(HE$2>=$C33,HE$2<=$D33,WEEKDAY(HE$2,2)<=5),100/$E33,0) -> 0
F34: Avance acumulado % | G34: =SUM($G33:G33) -> 0 | H34: =SUM($G33:H33) -> 0 | I34: =SUM($G33:I33) -> 0 | J34: =SUM($G33:J33) -> 0 | K34: =SUM($G33:K33) -> 0 | L34: =SUM($G33:L33) -> 0 | M34: =SUM($G33:M33) -> 0 | N34: =SUM($G33:N33) -> 0 | ... HE34: =SUM($G33:HE33) -> 100
A35: 1.2.4.1.9.1.3 | B35: [M3] C / F1 / OC / Losa / C1 / Hormigón | C35: =Datos!F18 -> 46406 | D35: =Datos!G18 -> 46406 | E35: =NETWORKDAYS(C35,D35) -> 1 | F35: Avance parcial % | G35: =IF(AND(G$2>=$C35,G$2<=$D35,WEEKDAY(G$2,2)<=5),100/$E35,0) -> 0 | H35: =IF(AND(H$2>=$C35,H$2<=$D35,WEEKDAY(H$2,2)<=5),100/$E35,0) -> 0 | I35: =IF(AND(I$2>=$C35,I$2<=$D35,WEEKDAY(I$2,2)<=5),100/$E35,0) -> 0 | J35: =IF(AND(J$2>=$C35,J$2<=$D35,WEEKDAY(J$2,2)<=5),100/$E35,0) -> 0 | K35: =IF(AND(K$2>=$C35,K$2<=$D35,WEEKDAY(K$2,2)<=5),100/$E35,0) -> 0 | L35: =IF(AND(L$2>=$C35,L$2<=$D35,WEEKDAY(L$2,2)<=5),100/$E35,0) -> 0 | M35: =IF(AND(M$2>=$C35,M$2<=$D35,WEEKDAY(M$2,2)<=5),100/$E35,0) -> 0 | N35: =IF(AND(N$2>=$C35,N$2<=$D35,WEEKDAY(N$2,2)<=5),100/$E35,0) -> 0 | ... HE35: =IF(AND(HE$2>=$C35,HE$2<=$D35,WEEKDAY(HE$2,2)<=5),100/$E35,0) -> 0
F36: Avance acumulado % | G36: =SUM($G35:G35) -> 0 | H36: =SUM($G35:H35) -> 0 | I36: =SUM($G35:I35) -> 0 | J36: =SUM($G35:J35) -> 0 | K36: =SUM($G35:K35) -> 0 | L36: =SUM($G35:L35) -> 0 | M36: =SUM($G35:M35) -> 0 | N36: =SUM($G35:N35) -> 0 | ... HE36: =SUM($G35:HE35) -> 100
A37: 1.2.4.1.9.2 | B37: C / F1 / OC / Losa / CICLO 02 | C37: =Datos!F19 -> 46400 | D37: =Datos!G19 -> 46415 | E37: =NETWORKDAYS(C37,D37) -> 12 | F37: Avance parcial % | G37: =IF(AND(G$2>=$C37,G$2<=$D37,WEEKDAY(G$2,2)<=5),100/$E37,0) -> 0 | H37: =IF(AND(H$2>=$C37,H$2<=$D37,WEEKDAY(H$2,2)<=5),100/$E37,0) -> 0 | I37: =IF(AND(I$2>=$C37,I$2<=$D37,WEEKDAY(I$2,2)<=5),100/$E37,0) -> 0 | J37: =IF(AND(J$2>=$C37,J$2<=$D37,WEEKDAY(J$2,2)<=5),100/$E37,0) -> 0 | K37: =IF(AND(K$2>=$C37,K$2<=$D37,WEEKDAY(K$2,2)<=5),100/$E37,0) -> 0 | L37: =IF(AND(L$2>=$C37,L$2<=$D37,WEEKDAY(L$2,2)<=5),100/$E37,0) -> 0 | M37: =IF(AND(M$2>=$C37,M$2<=$D37,WEEKDAY(M$2,2)<=5),100/$E37,0) -> 0 | N37: =IF(AND(N$2>=$C37,N$2<=$D37,WEEKDAY(N$2,2)<=5),100/$E37,0) -> 0 | ... HE37: =IF(AND(HE$2>=$C37,HE$2<=$D37,WEEKDAY(HE$2,2)<=5),100/$E37,0) -> 0
F38: Avance acumulado % | G38: =SUM($G37:G37) -> 0 | H38: =SUM($G37:H37) -> 0 | I38: =SUM($G37:I37) -> 0 | J38: =SUM($G37:J37) -> 0 | K38: =SUM($G37:K37) -> 0 | L38: =SUM($G37:L37) -> 0 | M38: =SUM($G37:M37) -> 0 | N38: =SUM($G37:N37) -> 0 | ... HE38: =SUM($G37:HE37) -> 100
A39: 1.2.4.1.9.2.3 | B39: [M3] C / F1 / OC / Losa / C2 / Hormigón | C39: =Datos!F20 -> 46413 | D39: =Datos!G20 -> 46415 | E39: =NETWORKDAYS(C39,D39) -> 3 | F39: Avance parcial % | G39: =IF(AND(G$2>=$C39,G$2<=$D39,WEEKDAY(G$2,2)<=5),100/$E39,0) -> 0 | H39: =IF(AND(H$2>=$C39,H$2<=$D39,WEEKDAY(H$2,2)<=5),100/$E39,0) -> 0 | I39: =IF(AND(I$2>=$C39,I$2<=$D39,WEEKDAY(I$2,2)<=5),100/$E39,0) -> 0 | J39: =IF(AND(J$2>=$C39,J$2<=$D39,WEEKDAY(J$2,2)<=5),100/$E39,0) -> 0 | K39: =IF(AND(K$2>=$C39,K$2<=$D39,WEEKDAY(K$2,2)<=5),100/$E39,0) -> 0 | L39: =IF(AND(L$2>=$C39,L$2<=$D39,WEEKDAY(L$2,2)<=5),100/$E39,0) -> 0 | M39: =IF(AND(M$2>=$C39,M$2<=$D39,WEEKDAY(M$2,2)<=5),100/$E39,0) -> 0 | N39: =IF(AND(N$2>=$C39,N$2<=$D39,WEEKDAY(N$2,2)<=5),100/$E39,0) -> 0 | ... HE39: =IF(AND(HE$2>=$C39,HE$2<=$D39,WEEKDAY(HE$2,2)<=5),100/$E39,0) -> 0
F40: Avance acumulado % | G40: =SUM($G39:G39) -> 0 | H40: =SUM($G39:H39) -> 0 | I40: =SUM($G39:I39) -> 0 | J40: =SUM($G39:J39) -> 0 | K40: =SUM($G39:K39) -> 0 | L40: =SUM($G39:L39) -> 0 | M40: =SUM($G39:M39) -> 0 | N40: =SUM($G39:N39) -> 0 | ... HE40: =SUM($G39:HE39) -> 100
...

Sheet Avance Semanal
A1: ITEM | B1: Actividad | C1: Tipo | D1: S04 14-sep al 20-sep | E1: S05 21-sep al 27-sep | F1: S06 28-sep al 04-oct | G1: S07 05-oct al 11-oct | H1: S08 12-oct al 18-oct | I1: S09 19-oct al 25-oct | J1: S10 26-oct al 01-nov | K1: S11 02-nov al 08-nov | L1: S12 09-nov al 15-nov | M1: S13 16-nov al 22-nov | N1: S14 23-nov al 29-nov | O1: S15 30-nov al 06-dic | P1: S16 07-dic al 13-dic | Q1: S17 14-dic al 20-dic | R1: S18 21-dic al 27-dic | S1: S19 28-dic al 03-ene | T1: S20 04-ene al 10-ene | U1: S21 11-ene al 17-ene | V1: S22 18-ene al 24-ene | W1: S23 25-ene al 31-ene | X1: S24 01-feb al 07-feb | Y1: S25 08-feb al 14-feb | Z1: S26 15-feb al 21-feb | AA1: S27 22-feb al 28-feb | AB1: S28 01-mar al 07-mar | AC1: S29 08-mar al 14-mar | AD1: S30 15-mar al 21-mar | AE1: S31 22-mar al 28-mar | AF1: S32 29-mar al 04-abr | AG1: S33 05-abr al 11-abr
A2: 1.2.4.1.7 | B2: C / F1 / OC / FUNDACIONES ESTANQUE & LOSA FUNDACIÓN | C2: Avance parcial % | D2: =SUM('Avance Diario'!G3:M3) -> 0 | E2: =SUM('Avance Diario'!N3:T3) -> 0 | F2: =SUM('Avance Diario'!U3:AA3) -> 0 | G2: =SUM('Avance Diario'!AB3:AH3) -> 0 | H2: =SUM('Avance Diario'!AI3:AO3) -> 0 | I2: =SUM('Avance Diario'!AP3:AV3) -> 0 | J2: =SUM('Avance Diario'!AW3:BC3) -> 0 | K2: =SUM('Avance Diario'!BD3:BJ3) -> 0 | L2: =SUM('Avance Diario'!BK3:BQ3) -> 13.888889 | M2: =SUM('Avance Diario'!BR3:BX3) -> 13.888889 | N2: =SUM('Avance Diario'!BY3:CE3) -> 13.888889 | O2: =SUM('Avance Diario'!CF3:CL3) -> 13.888889 | P2: =SUM('Avance Diario'!CM3:CS3) -> 13.888889 | Q2: =SUM('Avance Diario'!CT3:CZ3) -> 13.888889 | R2: =SUM('Avance Diario'!DA3:DG3) -> 13.888889 | S2: =SUM('Avance Diario'!DH3:DN3) -> 2.7777778 | T2: =SUM('Avance Diario'!DO3:DU3) -> 0 | U2: =SUM('Avance Diario'!DV3:EB3) -> 0 | V2: =SUM('Avance Diario'!EC3:EI3) -> 0 | W2: =SUM('Avance Diario'!EJ3:EP3) -> 0 | X2: =SUM('Avance Diario'!EQ3:EW3) -> 0 | Y2: =SUM('Avance Diario'!EX3:FD3) -> 0 | Z2: =SUM('Avance Diario'!FE3:FK3) -> 0 | AA2: =SUM('Avance Diario'!FL3:FR3) -> 0 | AB2: =SUM('Avance Diario'!FS3:FY3) -> 0 | AC2: =SUM('Avance Diario'!FZ3:GF3) -> 0 | AD2: =SUM('Avance Diario'!GG3:GM3) -> 0 | AE2: =SUM('Avance Diario'!GN3:GT3) -> 0 | AF2: =SUM('Avance Diario'!GU3:HA3) -> 0 | AG2: =SUM('Avance Diario'!HB3:HE3) -> 0
C3: Avance acumulado % | D3: =SUM($D2:D2) -> 0 | E3: =SUM($D2:E2) -> 0 | F3: =SUM($D2:F2) -> 0 | G3: =SUM($D2:G2) -> 0 | H3: =SUM($D2:H2) -> 0 | I3: =SUM($D2:I2) -> 0 | J3: =SUM($D2:J2) -> 0 | K3: =SUM($D2:K2) -> 0 | ... AG3: =SUM($D2:AG2) -> 100
A4: 1.2.4.1.7.1 | B4: C / F1 / OC / FE / CICLO 01 | C4: Avance parcial % | D4: =SUM('Avance Diario'!G5:M5) -> 0 | E4: =SUM('Avance Diario'!N5:T5) -> 0 | F4: =SUM('Avance Diario'!U5:AA5) -> 0 | G4: =SUM('Avance Diario'!AB5:AH5) -> 0 | H4: =SUM('Avance Diario'!AI5:AO5) -> 0 | I4: =SUM('Avance Diario'!AP5:AV5) -> 0 | J4: =SUM('Avance Diario'!AW5:BC5) -> 0 | K4: =SUM('Avance Diario'!BD5:BJ5) -> 0 | L4: =SUM('Avance Diario'!BK5:BQ5) -> 55.555556 | M4: =SUM('Avance Diario'!BR5:BX5) -> 44.444444 | N4: =SUM('Avance Diario'!BY5:CE5) -> 0 | O4: =SUM('Avance Diario'!CF5:CL5) -> 0 | P4: =SUM('Avance Diario'!CM5:CS5) -> 0 | Q4: =SUM('Avance Diario'!CT5:CZ5) -> 0 | R4: =SUM('Avance Diario'!DA5:DG5) -> 0 | S4: =SUM('Avance Diario'!DH5:DN5) -> 0 | T4: =SUM('Avance Diario'!DO5:DU5) -> 0 | U4: =SUM('Avance Diario'!DV5:EB5) -> 0 | V4: =SUM('Avance Diario'!EC5:EI5) -> 0 | W4: =SUM('Avance Diario'!EJ5:EP5) -> 0 | X4: =SUM('Avance Diario'!EQ5:EW5) -> 0 | Y4: =SUM('Avance Diario'!EX5:FD5) -> 0 | Z4: =SUM('Avance Diario'!FE5:FK5) -> 0 | AA4: =SUM('Avance Diario'!FL5:FR5) -> 0 | AB4: =SUM('Avance Diario'!FS5:FY5) -> 0 | AC4: =SUM('Avance Diario'!FZ5:GF5) -> 0 | AD4: =SUM('Avance Diario'!GG5:GM5) -> 0 | AE4: =SUM('Avance Diario'!GN5:GT5) -> 0 | AF4: =SUM('Avance Diario'!GU5:HA5) -> 0 | AG4: =SUM('Avance Diario'!HB5:HE5) -> 0
C5: Avance acumulado % | D5: =SUM($D4:D4) -> 0 | E5: =SUM($D4:E4) -> 0 | F5: =SUM($D4:F4) -> 0 | G5: =SUM($D4:G4) -> 0 | H5: =SUM($D4:H4) -> 0 | I5: =SUM($D4:I4) -> 0 | J5: =SUM($D4:J4) -> 0 | K5: =SUM($D4:K4) -> 0 | ... AG5: =SUM($D4:AG4) -> 100
A6: 1.2.4.1.7.1.3 | B6: [M3] C / F1 / OC / FE / C1 / Hormigón | C6: Avance parcial % | D6: =SUM('Avance Diario'!G7:M7) -> 0 | E6: =SUM('Avance Diario'!N7:T7) -> 0 | F6: =SUM('Avance Diario'!U7:AA7) -> 0 | G6: =SUM('Avance Diario'!AB7:AH7) -> 0 | H6: =SUM('Avance Diario'!AI7:AO7) -> 0 | I6: =SUM('Avance Diario'!AP7:AV7) -> 0 | J6: =SUM('Avance Diario'!AW7:BC7) -> 0 | K6: =SUM('Avance Diario'!BD7:BJ7) -> 0 | L6: =SUM('Avance Diario'!BK7:BQ7) -> 0 | M6: =SUM('Avance Diario'!BR7:BX7) -> 100 | N6: =SUM('Avance Diario'!BY7:CE7) -> 0 | O6: =SUM('Avance Diario'!CF7:CL7) -> 0 | P6: =SUM('Avance Diario'!CM7:CS7) -> 0 | Q6: =SUM('Avance Diario'!CT7:CZ7) -> 0 | R6: =SUM('Avance Diario'!DA7:DG7) -> 0 | S6: =SUM('Avance Diario'!DH7:DN7) -> 0 | T6: =SUM('Avance Diario'!DO7:DU7) -> 0 | U6: =SUM('Avance Diario'!DV7:EB7) -> 0 | V6: =SUM('Avance Diario'!EC7:EI7) -> 0 | W6: =SUM('Avance Diario'!EJ7:EP7) -> 0 | X6: =SUM('Avance Diario'!EQ7:EW7) -> 0 | Y6: =SUM('Avance Diario'!EX7:FD7) -> 0 | Z6: =SUM('Avance Diario'!FE7:FK7) -> 0 | AA6: =SUM('Avance Diario'!FL7:FR7) -> 0 | AB6: =SUM('Avance Diario'!FS7:FY7) -> 0 | AC6: =SUM('Avance Diario'!FZ7:GF7) -> 0 | AD6: =SUM('Avance Diario'!GG7:GM7) -> 0 | AE6: =SUM('Avance Diario'!GN7:GT7) -> 0 | AF6: =SUM('Avance Diario'!GU7:HA7) -> 0 | AG6: =SUM('Avance Diario'!HB7:HE7) -> 0
C7: Avance acumulado % | D7: =SUM($D6:D6) -> 0 | E7: =SUM($D6:E6) -> 0 | F7: =SUM($D6:F6) -> 0 | G7: =SUM($D6:G6) -> 0 | H7: =SUM($D6:H6) -> 0 | I7: =SUM($D6:I6) -> 0 | J7: =SUM($D6:J6) -> 0 | K7: =SUM($D6:K6) -> 0 | ... AG7: =SUM($D6:AG6) -> 100
A8: 1.2.4.1.7.2 | B8: C / F1 / OC / FE / CICLO 02 | C8: Avance parcial % | D8: =SUM('Avance Diario'!G9:M9) -> 0 | E8: =SUM('Avance Diario'!N9:T9) -> 0 | F8: =SUM('Avance Diario'!U9:AA9) -> 0 | G8: =SUM('Avance Diario'!AB9:AH9) -> 0 | H8: =SUM('Avance Diario'!AI9:AO9) -> 0 | I8: =SUM('Avance Diario'!AP9:AV9) -> 0 | J8: =SUM('Avance Diario'!AW9:BC9) -> 0 | K8: =SUM('Avance Diario'!BD9:BJ9) -> 0 | L8: =SUM('Avance Diario'!BK9:BQ9) -> 0 | M8: =SUM('Avance Diario'!BR9:BX9) -> 0 | N8: =SUM('Avance Diario'!BY9:CE9) -> 0 | O8: =SUM('Avance Diario'!CF9:CL9) -> 16.666667 | P8: =SUM('Avance Diario'!CM9:CS9) -> 41.666667 | Q8: =SUM('Avance Diario'!CT9:CZ9) -> 41.666667 | R8: =SUM('Avance Diario'!DA9:DG9) -> 0 | S8: =SUM('Avance Diario'!DH9:DN9) -> 0 | T8: =SUM('Avance Diario'!DO9:DU9) -> 0 | U8: =SUM('Avance Diario'!DV9:EB9) -> 0 | V8: =SUM('Avance Diario'!EC9:EI9) -> 0 | W8: =SUM('Avance Diario'!EJ9:EP9) -> 0 | X8: =SUM('Avance Diario'!EQ9:EW9) -> 0 | Y8: =SUM('Avance Diario'!EX9:FD9) -> 0 | Z8: =SUM('Avance Diario'!FE9:FK9) -> 0 | AA8: =SUM('Avance Diario'!FL9:FR9) -> 0 | AB8: =SUM('Avance Diario'!FS9:FY9) -> 0 | AC8: =SUM('Avance Diario'!FZ9:GF9) -> 0 | AD8: =SUM('Avance Diario'!GG9:GM9) -> 0 | AE8: =SUM('Avance Diario'!GN9:GT9) -> 0 | AF8: =SUM('Avance Diario'!GU9:HA9) -> 0 | AG8: =SUM('Avance Diario'!HB9:HE9) -> 0
C9: Avance acumulado % | D9: =SUM($D8:D8) -> 0 | E9: =SUM($D8:E8) -> 0 | F9: =SUM($D8:F8) -> 0 | G9: =SUM($D8:G8) -> 0 | H9: =SUM($D8:H8) -> 0 | I9: =SUM($D8:I8) -> 0 | J9: =SUM($D8:J8) -> 0 | K9: =SUM($D8:K8) -> 0 | ... AG9: =SUM($D8:AG8) -> 100
A10: 1.2.4.1.7.2.3 | B10: [M3] C / F1 / OC / FE / C2 / Hormigón | C10: Avance parcial % | D10: =SUM('Avance Diario'!G11:M11) -> 0 | E10: =SUM('Avance Diario'!N11:T11) -> 0 | F10: =SUM('Avance Diario'!U11:AA11) -> 0 | G10: =SUM('Avance Diario'!AB11:AH11) -> 0 | H10: =SUM('Avance Diario'!AI11:AO11) -> 0 | I10: =SUM('Avance Diario'!AP11:AV11) -> 0 | J10: =SUM('Avance Diario'!AW11:BC11) -> 0 | K10: =SUM('Avance Diario'!BD11:BJ11) -> 0 | L10: =SUM('Avance Diario'!BK11:BQ11) -> 0 | M10: =SUM('Avance Diario'!BR11:BX11) -> 0 | N10: =SUM('Avance Diario'!BY11:CE11) -> 0 | O10: =SUM('Avance Diario'!CF11:CL11) -> 0 | P10: =SUM('Avance Diario'!CM11:CS11) -> 0 | Q10: =SUM('Avance Diario'!CT11:CZ11) -> 100 | R10: =SUM('Avance Diario'!DA11:DG11) -> 0 | S10: =SUM('Avance Diario'!DH11:DN11) -> 0 | T10: =SUM('Avance Diario'!DO11:DU11) -> 0 | U10: =SUM('Avance Diario'!DV11:EB11) -> 0 | V10: =SUM('Avance Diario'!EC11:EI11) -> 0 | W10: =SUM('Avance Diario'!EJ11:EP11) -> 0 | X10: =SUM('Avance Diario'!EQ11:EW11) -> 0 | Y10: =SUM('Avance Diario'!EX11:FD11) -> 0 | Z10: =SUM('Avance Diario'!FE11:FK11) -> 0 | AA10: =SUM('Avance Diario'!FL11:FR11) -> 0 | AB10: =SUM('Avance Diario'!FS11:FY11) -> 0 | AC10: =SUM('Avance Diario'!FZ11:GF11) -> 0 | AD10: =SUM('Avance Diario'!GG11:GM11) -> 0 | AE10: =SUM('Avance Diario'!GN11:GT11) -> 0 | AF10: =SUM('Avance Diario'!GU11:HA11) -> 0 | AG10: =SUM('Avance Diario'!HB11:HE11) -> 0
C11: Avance acumulado % | D11: =SUM($D10:D10) -> 0 | E11: =SUM($D10:E10) -> 0 | F11: =SUM($D10:F10) -> 0 | G11: =SUM($D10:G10) -> 0 | H11: =SUM($D10:H10) -> 0 | I11: =SUM($D10:I10) -> 0 | J11: =SUM($D10:J10) -> 0 | K11: =SUM($D10:K10) -> 0 | ... AG11: =SUM($D10:AG10) -> 100
A12: 1.2.4.1.7.3 | B12: C / F1 / OC / FE / CICLO 03 | C12: Avance parcial % | D12: =SUM('Avance Diario'!G13:M13) -> 0 | E12: =SUM('Avance Diario'!N13:T13) -> 0 | F12: =SUM('Avance Diario'!U13:AA13) -> 0 | G12: =SUM('Avance Diario'!AB13:AH13) -> 0 | H12: =SUM('Avance Diario'!AI13:AO13) -> 0 | I12: =SUM('Avance Diario'!AP13:AV13) -> 0 | J12: =SUM('Avance Diario'!AW13:BC13) -> 0 | K12: =SUM('Avance Diario'!BD13:BJ13) -> 0 | L12: =SUM('Avance Diario'!BK13:BQ13) -> 0 | M12: =SUM('Avance Diario'!BR13:BX13) -> 0 | N12: =SUM('Avance Diario'!BY13:CE13) -> 0 | O12: =SUM('Avance Diario'!CF13:CL13) -> 0 | P12: =SUM('Avance Diario'!CM13:CS13) -> 8.3333333 | Q12: =SUM('Avance Diario'!CT13:CZ13) -> 41.666667 | R12: =SUM('Avance Diario'!DA13:DG13) -> 41.666667 | S12: =SUM('Avance Diario'!DH13:DN13) -> 8.3333333 | T12: =SUM('Avance Diario'!DO13:DU13) -> 0 | U12: =SUM('Avance Diario'!DV13:EB13) -> 0 | V12: =SUM('Avance Diario'!EC13:EI13) -> 0 | W12: =SUM('Avance Diario'!EJ13:EP13) -> 0 | X12: =SUM('Avance Diario'!EQ13:EW13) -> 0 | Y12: =SUM('Avance Diario'!EX13:FD13) -> 0 | Z12: =SUM('Avance Diario'!FE13:FK13) -> 0 | AA12: =SUM('Avance Diario'!FL13:FR13) -> 0 | AB12: =SUM('Avance Diario'!FS13:FY13) -> 0 | AC12: =SUM('Avance Diario'!FZ13:GF13) -> 0 | AD12: =SUM('Avance Diario'!GG13:GM13) -> 0 | AE12: =SUM('Avance Diario'!GN13:GT13) -> 0 | AF12: =SUM('Avance Diario'!GU13:HA13) -> 0 | AG12: =SUM('Avance Diario'!HB13:HE13) -> 0
C13: Avance acumulado % | D13: =SUM($D12:D12) -> 0 | E13: =SUM($D12:E12) -> 0 | F13: =SUM($D12:F12) -> 0 | G13: =SUM($D12:G12) -> 0 | H13: =SUM($D12:H12) -> 0 | I13: =SUM($D12:I12) -> 0 | J13: =SUM($D12:J12) -> 0 | K13: =SUM($D12:K12) -> 0 | ... AG13: =SUM($D12:AG12) -> 100
A14: 1.2.4.1.7.3.3 | B14: [M3] C / F1 / OC / FE / C3 / Hormigón | C14: Avance parcial % | D14: =SUM('Avance Diario'!G15:M15) -> 0 | E14: =SUM('Avance Diario'!N15:T15) -> 0 | F14: =SUM('Avance Diario'!U15:AA15) -> 0 | G14: =SUM('Avance Diario'!AB15:AH15) -> 0 | H14: =SUM('Avance Diario'!AI15:AO15) -> 0 | I14: =SUM('Avance Diario'!AP15:AV15) -> 0 | J14: =SUM('Avance Diario'!AW15:BC15) -> 0 | K14: =SUM('Avance Diario'!BD15:BJ15) -> 0 | L14: =SUM('Avance Diario'!BK15:BQ15) -> 0 | M14: =SUM('Avance Diario'!BR15:BX15) -> 0 | N14: =SUM('Avance Diario'!BY15:CE15) -> 0 | O14: =SUM('Avance Diario'!CF15:CL15) -> 0 | P14: =SUM('Avance Diario'!CM15:CS15) -> 0 | Q14: =SUM('Avance Diario'!CT15:CZ15) -> 0 | R14: =SUM('Avance Diario'!DA15:DG15) -> 80 | S14: =SUM('Avance Diario'!DH15:DN15) -> 20 | T14: =SUM('Avance Diario'!DO15:DU15) -> 0 | U14: =SUM('Avance Diario'!DV15:EB15) -> 0 | V14: =SUM('Avance Diario'!EC15:EI15) -> 0 | W14: =SUM('Avance Diario'!EJ15:EP15) -> 0 | X14: =SUM('Avance Diario'!EQ15:EW15) -> 0 | Y14: =SUM('Avance Diario'!EX15:FD15) -> 0 | Z14: =SUM('Avance Diario'!FE15:FK15) -> 0 | AA14: =SUM('Avance Diario'!FL15:FR15) -> 0 | AB14: =SUM('Avance Diario'!FS15:FY15) -> 0 | AC14: =SUM('Avance Diario'!FZ15:GF15) -> 0 | AD14: =SUM('Avance Diario'!GG15:GM15) -> 0 | AE14: =SUM('Avance Diario'!GN15:GT15) -> 0 | AF14: =SUM('Avance Diario'!GU15:HA15) -> 0 | AG14: =SUM('Avance Diario'!HB15:HE15) -> 0
C15: Avance acumulado % | D15: =SUM($D14:D14) -> 0 | E15: =SUM($D14:E14) -> 0 | F15: =SUM($D14:F14) -> 0 | G15: =SUM($D14:G14) -> 0 | H15: =SUM($D14:H14) -> 0 | I15: =SUM($D14:I14) -> 0 | J15: =SUM($D14:J14) -> 0 | K15: =SUM($D14:K14) -> 0 | ... AG15: =SUM($D14:AG14) -> 100
A16: 1.2.4.1.8 | B16: C / F1 / OC / ELEV. MUROS Y PILARES ESTANQUE | C16: Avance parcial % | D16: =SUM('Avance Diario'!G17:M17) -> 0 | E16: =SUM('Avance Diario'!N17:T17) -> 0 | F16: =SUM('Avance Diario'!U17:AA17) -> 0 | G16: =SUM('Avance Diario'!AB17:AH17) -> 0 | H16: =SUM('Avance Diario'!AI17:AO17) -> 0 | I16: =SUM('Avance Diario'!AP17:AV17) -> 0 | J16: =SUM('Avance Diario'!AW17:BC17) -> 0 | K16: =SUM('Avance Diario'!BD17:BJ17) -> 0 | L16: =SUM('Avance Diario'!BK17:BQ17) -> 0 | M16: =SUM('Avance Diario'!BR17:BX17) -> 2.7027027 | N16: =SUM('Avance Diario'!BY17:CE17) -> 13.513514 | O16: =SUM('Avance Diario'!CF17:CL17) -> 13.513514 | P16: =SUM('Avance Diario'!CM17:CS17) -> 13.513514 | Q16: =SUM('Avance Diario'!CT17:CZ17) -> 13.513514 | R16: =SUM('Avance Diario'!DA17:DG17) -> 13.513514 | S16: =SUM('Avance Diario'!DH17:DN17) -> 13.513514 | T16: =SUM('Avance Diario'!DO17:DU17) -> 13.513514 | U16: =SUM('Avance Diario'!DV17:EB17) -> 2.7027027 | V16: =SUM('Avance Diario'!EC17:EI17) -> 0 | W16: =SUM('Avance Diario'!EJ17:EP17) -> 0 | X16: =SUM('Avance Diario'!EQ17:EW17) -> 0 | Y16: =SUM('Avance Diario'!EX17:FD17) -> 0 | Z16: =SUM('Avance Diario'!FE17:FK17) -> 0 | AA16: =SUM('Avance Diario'!FL17:FR17) -> 0 | AB16: =SUM('Avance Diario'!FS17:FY17) -> 0 | AC16: =SUM('Avance Diario'!FZ17:GF17) -> 0 | AD16: =SUM('Avance Diario'!GG17:GM17) -> 0 | AE16: =SUM('Avance Diario'!GN17:GT17) -> 0 | AF16: =SUM('Avance Diario'!GU17:HA17) -> 0 | AG16: =SUM('Avance Diario'!HB17:HE17) -> 0
C17: Avance acumulado % | D17: =SUM($D16:D16) -> 0 | E17: =SUM($D16:E16) -> 0 | F17: =SUM($D16:F16) -> 0 | G17: =SUM($D16:G16) -> 0 | H17: =SUM($D16:H16) -> 0 | I17: =SUM($D16:I16) -> 0 | J17: =SUM($D16:J16) -> 0 | K17: =SUM($D16:K16) -> 0 | ... AG17: =SUM($D16:AG16) -> 100
A18: 1.2.4.1.8.1 | B18: C / F1 / OC / Elev / CICLO 01 | C18: Avance parcial % | D18: =SUM('Avance Diario'!G19:M19) -> 0 | E18: =SUM('Avance Diario'!N19:T19) -> 0 | F18: =SUM('Avance Diario'!U19:AA19) -> 0 | G18: =SUM('Avance Diario'!AB19:AH19) -> 0 | H18: =SUM('Avance Diario'!AI19:AO19) -> 0 | I18: =SUM('Avance Diario'!AP19:AV19) -> 0 | J18: =SUM('Avance Diario'!AW19:BC19) -> 0 | K18: =SUM('Avance Diario'!BD19:BJ19) -> 0 | L18: =SUM('Avance Diario'!BK19:BQ19) -> 0 | M18: =SUM('Avance Diario'!BR19:BX19) -> 3.4482759 | N18: =SUM('Avance Diario'!BY19:CE19) -> 17.241379 | O18: =SUM('Avance Diario'!CF19:CL19) -> 17.241379 | P18: =SUM('Avance Diario'!CM19:CS19) -> 17.241379 | Q18: =SUM('Avance Diario'!CT19:CZ19) -> 17.241379 | R18: =SUM('Avance Diario'!DA19:DG19) -> 17.241379 | S18: =SUM('Avance Diario'!DH19:DN19) -> 10.344828 | T18: =SUM('Avance Diario'!DO19:DU19) -> 0 | U18: =SUM('Avance Diario'!DV19:EB19) -> 0 | V18: =SUM('Avance Diario'!EC19:EI19) -> 0 | W18: =SUM('Avance Diario'!EJ19:EP19) -> 0 | X18: =SUM('Avance Diario'!EQ19:EW19) -> 0 | Y18: =SUM('Avance Diario'!EX19:FD19) -> 0 | Z18: =SUM('Avance Diario'!FE19:FK19) -> 0 | AA18: =SUM('Avance Diario'!FL19:FR19) -> 0 | AB18: =SUM('Avance Diario'!FS19:FY19) -> 0 | AC18: =SUM('Avance Diario'!FZ19:GF19) -> 0 | AD18: =SUM('Avance Diario'!GG19:GM19) -> 0 | AE18: =SUM('Avance Diario'!GN19:GT19) -> 0 | AF18: =SUM('Avance Diario'!GU19:HA19) -> 0 | AG18: =SUM('Avance Diario'!HB19:HE19) -> 0
C19: Avance acumulado % | D19: =SUM($D18:D18) -> 0 | E19: =SUM($D18:E18) -> 0 | F19: =SUM($D18:F18) -> 0 | G19: =SUM($D18:G18) -> 0 | H19: =SUM($D18:H18) -> 0 | I19: =SUM($D18:I18) -> 0 | J19: =SUM($D18:J18) -> 0 | K19: =SUM($D18:K18) -> 0 | ... AG19: =SUM($D18:AG18) -> 100
A20: 1.2.4.1.8.1.3 | B20: [M3] C / F1 / OC / Elev / C1 / Hormigón | C20: Avance parcial % | D20: =SUM('Avance Diario'!G21:M21) -> 0 | E20: =SUM('Avance Diario'!N21:T21) -> 0 | F20: =SUM('Avance Diario'!U21:AA21) -> 0 | G20: =SUM('Avance Diario'!AB21:AH21) -> 0 | H20: =SUM('Avance Diario'!AI21:AO21) -> 0 | I20: =SUM('Avance Diario'!AP21:AV21) -> 0 | J20: =SUM('Avance Diario'!AW21:BC21) -> 0 | K20: =SUM('Avance Diario'!BD21:BJ21) -> 0 | L20: =SUM('Avance Diario'!BK21:BQ21) -> 0 | M20: =SUM('Avance Diario'!BR21:BX21) -> 0 | N20: =SUM('Avance Diario'!BY21:CE21) -> 0 | O20: =SUM('Avance Diario'!CF21:CL21) -> 0 | P20: =SUM('Avance Diario'!CM21:CS21) -> 0 | Q20: =SUM('Avance Diario'!CT21:CZ21) -> 0 | R20: =SUM('Avance Diario'!DA21:DG21) -> 0 | S20: =SUM('Avance Diario'!DH21:DN21) -> 100 | T20: =SUM('Avance Diario'!DO21:DU21) -> 0 | U20: =SUM('Avance Diario'!DV21:EB21) -> 0 | V20: =SUM('Avance Diario'!EC21:EI21) -> 0 | W20: =SUM('Avance Diario'!EJ21:EP21) -> 0 | X20: =SUM('Avance Diario'!EQ21:EW21) -> 0 | Y20: =SUM('Avance Diario'!EX21:FD21) -> 0 | Z20: =SUM('Avance Diario'!FE21:FK21) -> 0 | AA20: =SUM('Avance Diario'!FL21:FR21) -> 0 | AB20: =SUM('Avance Diario'!FS21:FY21) -> 0 | AC20: =SUM('Avance Diario'!FZ21:GF21) -> 0 | AD20: =SUM('Avance Diario'!GG21:GM21) -> 0 | AE20: =SUM('Avance Diario'!GN21:GT21) -> 0 | AF20: =SUM('Avance Diario'!GU21:HA21) -> 0 | AG20: =SUM('Avance Diario'!HB21:HE21) -> 0
C21: Avance acumulado % | D21: =SUM($D20:D20) -> 0 | E21: =SUM($D20:E20) -> 0 | F21: =SUM($D20:F20) -> 0 | G21: =SUM($D20:G20) -> 0 | H21: =SUM($D20:H20) -> 0 | I21: =SUM($D20:I20) -> 0 | J21: =SUM($D20:J20) -> 0 | K21: =SUM($D20:K20) -> 0 | ... AG21: =SUM($D20:AG20) -> 100
A22: 1.2.4.1.8.2 | B22: C / F1 / OC / Elev / CICLO 02 | C22: Avance parcial % | D22: =SUM('Avance Diario'!G23:M23) -> 0 | E22: =SUM('Avance Diario'!N23:T23) -> 0 | F22: =SUM('Avance Diario'!U23:AA23) -> 0 | G22: =SUM('Avance Diario'!AB23:AH23) -> 0 | H22: =SUM('Avance Diario'!AI23:AO23) -> 0 | I22: =SUM('Avance Diario'!AP23:AV23) -> 0 | J22: =SUM('Avance Diario'!AW23:BC23) -> 0 | K22: =SUM('Avance Diario'!BD23:BJ23) -> 0 | L22: =SUM('Avance Diario'!BK23:BQ23) -> 0 | M22: =SUM('Avance Diario'!BR23:BX23) -> 0 | N22: =SUM('Avance Diario'!BY23:CE23) -> 0 | O22: =SUM('Avance Diario'!CF23:CL23) -> 0 | P22: =SUM('Avance Diario'!CM23:CS23) -> 0 | Q22: =SUM('Avance Diario'!CT23:CZ23) -> 0 | R22: =SUM('Avance Diario'!DA23:DG23) -> 41.666667 | S22: =SUM('Avance Diario'!DH23:DN23) -> 41.666667 | T22: =SUM('Avance Diario'!DO23:DU23) -> 16.666667 | U22: =SUM('Avance Diario'!DV23:EB23) -> 0 | V22: =SUM('Avance Diario'!EC23:EI23) -> 0 | W22: =SUM('Avance Diario'!EJ23:EP23) -> 0 | X22: =SUM('Avance Diario'!EQ23:EW23) -> 0 | Y22: =SUM('Avance Diario'!EX23:FD23) -> 0 | Z22: =SUM('Avance Diario'!FE23:FK23) -> 0 | AA22: =SUM('Avance Diario'!FL23:FR23) -> 0 | AB22: =SUM('Avance Diario'!FS23:FY23) -> 0 | AC22: =SUM('Avance Diario'!FZ23:GF23) -> 0 | AD22: =SUM('Avance Diario'!GG23:GM23) -> 0 | AE22: =SUM('Avance Diario'!GN23:GT23) -> 0 | AF22: =SUM('Avance Diario'!GU23:HA23) -> 0 | AG22: =SUM('Avance Diario'!HB23:HE23) -> 0
C23: Avance acumulado % | D23: =SUM($D22:D22) -> 0 | E23: =SUM($D22:E22) -> 0 | F23: =SUM($D22:F22) -> 0 | G23: =SUM($D22:G22) -> 0 | H23: =SUM($D22:H22) -> 0 | I23: =SUM($D22:I22) -> 0 | J23: =SUM($D22:J22) -> 0 | K23: =SUM($D22:K22) -> 0 | ... AG23: =SUM($D22:AG22) -> 100
A24: 1.2.4.1.8.2.3 | B24: [M3] C / F1 / OC / Elev / C2 / Hormigón | C24: Avance parcial % | D24: =SUM('Avance Diario'!G25:M25) -> 0 | E24: =SUM('Avance Diario'!N25:T25) -> 0 | F24: =SUM('Avance Diario'!U25:AA25) -> 0 | G24: =SUM('Avance Diario'!AB25:AH25) -> 0 | H24: =SUM('Avance Diario'!AI25:AO25) -> 0 | I24: =SUM('Avance Diario'!AP25:AV25) -> 0 | J24: =SUM('Avance Diario'!AW25:BC25) -> 0 | K24: =SUM('Avance Diario'!BD25:BJ25) -> 0 | L24: =SUM('Avance Diario'!BK25:BQ25) -> 0 | M24: =SUM('Avance Diario'!BR25:BX25) -> 0 | N24: =SUM('Avance Diario'!BY25:CE25) -> 0 | O24: =SUM('Avance Diario'!CF25:CL25) -> 0 | P24: =SUM('Avance Diario'!CM25:CS25) -> 0 | Q24: =SUM('Avance Diario'!CT25:CZ25) -> 0 | R24: =SUM('Avance Diario'!DA25:DG25) -> 0 | S24: =SUM('Avance Diario'!DH25:DN25) -> 0 | T24: =SUM('Avance Diario'!DO25:DU25) -> 100 | U24: =SUM('Avance Diario'!DV25:EB25) -> 0 | V24: =SUM('Avance Diario'!EC25:EI25) -> 0 | W24: =SUM('Avance Diario'!EJ25:EP25) -> 0 | X24: =SUM('Avance Diario'!EQ25:EW25) -> 0 | Y24: =SUM('Avance Diario'!EX25:FD25) -> 0 | Z24: =SUM('Avance Diario'!FE25:FK25) -> 0 | AA24: =SUM('Avance Diario'!FL25:FR25) -> 0 | AB24: =SUM('Avance Diario'!FS25:FY25) -> 0 | AC24: =SUM('Avance Diario'!FZ25:GF25) -> 0 | AD24: =SUM('Avance Diario'!GG25:GM25) -> 0 | AE24: =SUM('Avance Diario'!GN25:GT25) -> 0 | AF24: =SUM('Avance Diario'!GU25:HA25) -> 0 | AG24: =SUM('Avance Diario'!HB25:HE25) -> 0
C25: Avance acumulado % | D25: =SUM($D24:D24) -> 0 | E25: =SUM($D24:E24) -> 0 | F25: =SUM($D24:F24) -> 0 | G25: =SUM($D24:G24) -> 0 | H25: =SUM($D24:H24) -> 0 | I25: =SUM($D24:I24) -> 0 | J25: =SUM($D24:J24) -> 0 | K25: =SUM($D24:K24) -> 0 | ... AG25: =SUM($D24:AG24) -> 100
A26: 1.2.4.1.8.3 | B26: C / F1 / OC / Elev / CICLO 03 | C26: Avance parcial % | D26: =SUM('Avance Diario'!G27:M27) -> 0 | E26: =SUM('Avance Diario'!N27:T27) -> 0 | F26: =SUM('Avance Diario'!U27:AA27) -> 0 | G26: =SUM('Avance Diario'!AB27:AH27) -> 0 | H26: =SUM('Avance Diario'!AI27:AO27) -> 0 | I26: =SUM('Avance Diario'!AP27:AV27) -> 0 | J26: =SUM('Avance Diario'!AW27:BC27) -> 0 | K26: =SUM('Avance Diario'!BD27:BJ27) -> 0 | L26: =SUM('Avance Diario'!BK27:BQ27) -> 0 | M26: =SUM('Avance Diario'!BR27:BX27) -> 0 | N26: =SUM('Avance Diario'!BY27:CE27) -> 0 | O26: =SUM('Avance Diario'!CF27:CL27) -> 0 | P26: =SUM('Avance Diario'!CM27:CS27) -> 0 | Q26: =SUM('Avance Diario'!CT27:CZ27) -> 0 | R26: =SUM('Avance Diario'!DA27:DG27) -> 0 | S26: =SUM('Avance Diario'!DH27:DN27) -> 40 | T26: =SUM('Avance Diario'!DO27:DU27) -> 50 | U26: =SUM('Avance Diario'!DV27:EB27) -> 10 | V26: =SUM('Avance Diario'!EC27:EI27) -> 0 | W26: =SUM('Avance Diario'!EJ27:EP27) -> 0 | X26: =SUM('Avance Diario'!EQ27:EW27) -> 0 | Y26: =SUM('Avance Diario'!EX27:FD27) -> 0 | Z26: =SUM('Avance Diario'!FE27:FK27) -> 0 | AA26: =SUM('Avance Diario'!FL27:FR27) -> 0 | AB26: =SUM('Avance Diario'!FS27:FY27) -> 0 | AC26: =SUM('Avance Diario'!FZ27:GF27) -> 0 | AD26: =SUM('Avance Diario'!GG27:GM27) -> 0 | AE26: =SUM('Avance Diario'!GN27:GT27) -> 0 | AF26: =SUM('Avance Diario'!GU27:HA27) -> 0 | AG26: =SUM('Avance Diario'!HB27:HE27) -> 0
C27: Avance acumulado % | D27: =SUM($D26:D26) -> 0 | E27: =SUM($D26:E26) -> 0 | F27: =SUM($D26:F26) -> 0 | G27: =SUM($D26:G26) -> 0 | H27: =SUM($D26:H26) -> 0 | I27: =SUM($D26:I26) -> 0 | J27: =SUM($D26:J26) -> 0 | K27: =SUM($D26:K26) -> 0 | ... AG27: =SUM($D26:AG26) -> 100
A28: 1.2.4.1.8.3.3 | B28: [M3] C / F1 / OC / Elev / C3 / Hormigón | C28: Avance parcial % | D28: =SUM('Avance Diario'!G29:M29) -> 0 | E28: =SUM('Avance Diario'!N29:T29) -> 0 | F28: =SUM('Avance Diario'!U29:AA29) -> 0 | G28: =SUM('Avance Diario'!AB29:AH29) -> 0 | H28: =SUM('Avance Diario'!AI29:AO29) -> 0 | I28: =SUM('Avance Diario'!AP29:AV29) -> 0 | J28: =SUM('Avance Diario'!AW29:BC29) -> 0 | K28: =SUM('Avance Diario'!BD29:BJ29) -> 0 | L28: =SUM('Avance Diario'!BK29:BQ29) -> 0 | M28: =SUM('Avance Diario'!BR29:BX29) -> 0 | N28: =SUM('Avance Diario'!BY29:CE29) -> 0 | O28: =SUM('Avance Diario'!CF29:CL29) -> 0 | P28: =SUM('Avance Diario'!CM29:CS29) -> 0 | Q28: =SUM('Avance Diario'!CT29:CZ29) -> 0 | R28: =SUM('Avance Diario'!DA29:DG29) -> 0 | S28: =SUM('Avance Diario'!DH29:DN29) -> 0 | T28: =SUM('Avance Diario'!DO29:DU29) -> 50 | U28: =SUM('Avance Diario'!DV29:EB29) -> 50 | V28: =SUM('Avance Diario'!EC29:EI29) -> 0 | W28: =SUM('Avance Diario'!EJ29:EP29) -> 0 | X28: =SUM('Avance Diario'!EQ29:EW29) -> 0 | Y28: =SUM('Avance Diario'!EX29:FD29) -> 0 | Z28: =SUM('Avance Diario'!FE29:FK29) -> 0 | AA28: =SUM('Avance Diario'!FL29:FR29) -> 0 | AB28: =SUM('Avance Diario'!FS29:FY29) -> 0 | AC28: =SUM('Avance Diario'!FZ29:GF29) -> 0 | AD28: =SUM('Avance Diario'!GG29:GM29) -> 0 | AE28: =SUM('Avance Diario'!GN29:GT29) -> 0 | AF28: =SUM('Avance Diario'!GU29:HA29) -> 0 | AG28: =SUM('Avance Diario'!HB29:HE29) -> 0
C29: Avance acumulado % | D29: =SUM($D28:D28) -> 0 | E29: =SUM($D28:E28) -> 0 | F29: =SUM($D28:F28) -> 0 | G29: =SUM($D28:G28) -> 0 | H29: =SUM($D28:H28) -> 0 | I29: =SUM($D28:I28) -> 0 | J29: =SUM($D28:J28) -> 0 | K29: =SUM($D28:K28) -> 0 | ... AG29: =SUM($D28:AG28) -> 100
A30: 1.2.4.1.9 | B30: C / F1 / OC / LOSA SUP. ESTANQUE | C30: Avance parcial % | D30: =SUM('Avance Diario'!G31:M31) -> 0 | E30: =SUM('Avance Diario'!N31:T31) -> 0 | F30: =SUM('Avance Diario'!U31:AA31) -> 0 | G30: =SUM('Avance Diario'!AB31:AH31) -> 0 | H30: =SUM('Avance Diario'!AI31:AO31) -> 0 | I30: =SUM('Avance Diario'!AP31:AV31) -> 0 | J30: =SUM('Avance Diario'!AW31:BC31) -> 0 | K30: =SUM('Avance Diario'!BD31:BJ31) -> 0 | L30: =SUM('Avance Diario'!BK31:BQ31) -> 0 | M30: =SUM('Avance Diario'!BR31:BX31) -> 0 | N30: =SUM('Avance Diario'!BY31:CE31) -> 0 | O30: =SUM('Avance Diario'!CF31:CL31) -> 0 | P30: =SUM('Avance Diario'!CM31:CS31) -> 0 | Q30: =SUM('Avance Diario'!CT31:CZ31) -> 0 | R30: =SUM('Avance Diario'!DA31:DG31) -> 0 | S30: =SUM('Avance Diario'!DH31:DN31) -> 0 | T30: =SUM('Avance Diario'!DO31:DU31) -> 13.636364 | U30: =SUM('Avance Diario'!DV31:EB31) -> 22.727273 | V30: =SUM('Avance Diario'!EC31:EI31) -> 22.727273 | W30: =SUM('Avance Diario'!EJ31:EP31) -> 22.727273 | X30: =SUM('Avance Diario'!EQ31:EW31) -> 18.181818 | Y30: =SUM('Avance Diario'!EX31:FD31) -> 0 | Z30: =SUM('Avance Diario'!FE31:FK31) -> 0 | AA30: =SUM('Avance Diario'!FL31:FR31) -> 0 | AB30: =SUM('Avance Diario'!FS31:FY31) -> 0 | AC30: =SUM('Avance Diario'!FZ31:GF31) -> 0 | AD30: =SUM('Avance Diario'!GG31:GM31) -> 0 | AE30: =SUM('Avance Diario'!GN31:GT31) -> 0 | AF30: =SUM('Avance Diario'!GU31:HA31) -> 0 | AG30: =SUM('Avance Diario'!HB31:HE31) -> 0
C31: Avance acumulado % | D31: =SUM($D30:D30) -> 0 | E31: =SUM($D30:E30) -> 0 | F31: =SUM($D30:F30) -> 0 | G31: =SUM($D30:G30) -> 0 | H31: =SUM($D30:H30) -> 0 | I31: =SUM($D30:I30) -> 0 | J31: =SUM($D30:J30) -> 0 | K31: =SUM($D30:K30) -> 0 | ... AG31: =SUM($D30:AG30) -> 100
A32: 1.2.4.1.9.1 | B32: C / F1 / OC / Losa / CICLO 01 | C32: Avance parcial % | D32: =SUM('Avance Diario'!G33:M33) -> 0 | E32: =SUM('Avance Diario'!N33:T33) -> 0 | F32: =SUM('Avance Diario'!U33:AA33) -> 0 | G32: =SUM('Avance Diario'!AB33:AH33) -> 0 | H32: =SUM('Avance Diario'!AI33:AO33) -> 0 | I32: =SUM('Avance Diario'!AP33:AV33) -> 0 | J32: =SUM('Avance Diario'!AW33:BC33) -> 0 | K32: =SUM('Avance Diario'!BD33:BJ33) -> 0 | L32: =SUM('Avance Diario'!BK33:BQ33) -> 0 | M32: =SUM('Avance Diario'!BR33:BX33) -> 0 | N32: =SUM('Avance Diario'!BY33:CE33) -> 0 | O32: =SUM('Avance Diario'!CF33:CL33) -> 0 | P32: =SUM('Avance Diario'!CM33:CS33) -> 0 | Q32: =SUM('Avance Diario'!CT33:CZ33) -> 0 | R32: =SUM('Avance Diario'!DA33:DG33) -> 0 | S32: =SUM('Avance Diario'!DH33:DN33) -> 0 | T32: =SUM('Avance Diario'!DO33:DU33) -> 30 | U32: =SUM('Avance Diario'!DV33:EB33) -> 50 | V32: =SUM('Avance Diario'!EC33:EI33) -> 20 | W32: =SUM('Avance Diario'!EJ33:EP33) -> 0 | X32: =SUM('Avance Diario'!EQ33:EW33) -> 0 | Y32: =SUM('Avance Diario'!EX33:FD33) -> 0 | Z32: =SUM('Avance Diario'!FE33:FK33) -> 0 | AA32: =SUM('Avance Diario'!FL33:FR33) -> 0 | AB32: =SUM('Avance Diario'!FS33:FY33) -> 0 | AC32: =SUM('Avance Diario'!FZ33:GF33) -> 0 | AD32: =SUM('Avance Diario'!GG33:GM33) -> 0 | AE32: =SUM('Avance Diario'!GN33:GT33) -> 0 | AF32: =SUM('Avance Diario'!GU33:HA33) -> 0 | AG32: =SUM('Avance Diario'!HB33:HE33) -> 0
C33: Avance acumulado % | D33: =SUM($D32:D32) -> 0 | E33: =SUM($D32:E32) -> 0 | F33: =SUM($D32:F32) -> 0 | G33: =SUM($D32:G32) -> 0 | H33: =SUM($D32:H32) -> 0 | I33: =SUM($D32:I32) -> 0 | J33: =SUM($D32:J32) -> 0 | K33: =SUM($D32:K32) -> 0 | ... AG33: =SUM($D32:AG32) -> 100
A34: 1.2.4.1.9.1.3 | B34: [M3] C / F1 / OC / Losa / C1 / Hormigón | C34: Avance parcial % | D34: =SUM('Avance Diario'!G35:M35) -> 0 | E34: =SUM('Avance Diario'!N35:T35) -> 0 | F34: =SUM('Avance Diario'!U35:AA35) -> 0 | G34: =SUM('Avance Diario'!AB35:AH35) -> 0 | H34: =SUM('Avance Diario'!AI35:AO35) -> 0 | I34: =SUM('Avance Diario'!AP35:AV35) -> 0 | J34: =SUM('Avance Diario'!AW35:BC35) -> 0 | K34: =SUM('Avance Diario'!BD35:BJ35) -> 0 | L34: =SUM('Avance Diario'!BK35:BQ35) -> 0 | M34: =SUM('Avance Diario'!BR35:BX35) -> 0 | N34: =SUM('Avance Diario'!BY35:CE35) -> 0 | O34: =SUM('Avance Diario'!CF35:CL35) -> 0 | P34: =SUM('Avance Diario'!CM35:CS35) -> 0 | Q34: =SUM('Avance Diario'!CT35:CZ35) -> 0 | R34: =SUM('Avance Diario'!DA35:DG35) -> 0 | S34: =SUM('Avance Diario'!DH35:DN35) -> 0 | T34: =SUM('Avance Diario'!DO35:DU35) -> 0 | U34: =SUM('Avance Diario'!DV35:EB35) -> 0 | V34: =SUM('Avance Diario'!EC35:EI35) -> 100 | W34: =SUM('Avance Diario'!EJ35:EP35) -> 0 | X34: =SUM('Avance Diario'!EQ35:EW35) -> 0 | Y34: =SUM('Avance Diario'!EX35:FD35) -> 0 | Z34: =SUM('Avance Diario'!FE35:FK35) -> 0 | AA34: =SUM('Avance Diario'!FL35:FR35) -> 0 | AB34: =SUM('Avance Diario'!FS35:FY35) -> 0 | AC34: =SUM('Avance Diario'!FZ35:GF35) -> 0 | AD34: =SUM('Avance Diario'!GG35:GM35) -> 0 | AE34: =SUM('Avance Diario'!GN35:GT35) -> 0 | AF34: =SUM('Avance Diario'!GU35:HA35) -> 0 | AG34: =SUM('Avance Diario'!HB35:HE35) -> 0
C35: Avance acumulado % | D35: =SUM($D34:D34) -> 0 | E35: =SUM($D34:E34) -> 0 | F35: =SUM($D34:F34) -> 0 | G35: =SUM($D34:G34) -> 0 | H35: =SUM($D34:H34) -> 0 | I35: =SUM($D34:I34) -> 0 | J35: =SUM($D34:J34) -> 0 | K35: =SUM($D34:K34) -> 0 | ... AG35: =SUM($D34:AG34) -> 100
A36: 1.2.4.1.9.2 | B36: C / F1 / OC / Losa / CICLO 02 | C36: Avance parcial % | D36: =SUM('Avance Diario'!G37:M37) -> 0 | E36: =SUM('Avance Diario'!N37:T37) -> 0 | F36: =SUM('Avance Diario'!U37:AA37) -> 0 | G36: =SUM('Avance Diario'!AB37:AH37) -> 0 | H36: =SUM('Avance Diario'!AI37:AO37) -> 0 | I36: =SUM('Avance Diario'!AP37:AV37) -> 0 | J36: =SUM('Avance Diario'!AW37:BC37) -> 0 | K36: =SUM('Avance Diario'!BD37:BJ37) -> 0 | L36: =SUM('Avance Diario'!BK37:BQ37) -> 0 | M36: =SUM('Avance Diario'!BR37:BX37) -> 0 | N36: =SUM('Avance Diario'!BY37:CE37) -> 0 | O36: =SUM('Avance Diario'!CF37:CL37) -> 0 | P36: =SUM('Avance Diario'!CM37:CS37) -> 0 | Q36: =SUM('Avance Diario'!CT37:CZ37) -> 0 | R36: =SUM('Avance Diario'!DA37:DG37) -> 0 | S36: =SUM('Avance Diario'!DH37:DN37) -> 0 | T36: =SUM('Avance Diario'!DO37:DU37) -> 0 | U36: =SUM('Avance Diario'!DV37:EB37) -> 25 | V36: =SUM('Avance Diario'!EC37:EI37) -> 41.666667 | W36: =SUM('Avance Diario'!EJ37:EP37) -> 33.333333 | X36: =SUM('Avance Diario'!EQ37:EW37) -> 0 | Y36: =SUM('Avance Diario'!EX37:FD37) -> 0 | Z36: =SUM('Avance Diario'!FE37:FK37) -> 0 | AA36: =SUM('Avance Diario'!FL37:FR37) -> 0 | AB36: =SUM('Avance Diario'!FS37:FY37) -> 0 | AC36: =SUM('Avance Diario'!FZ37:GF37) -> 0 | AD36: =SUM('Avance Diario'!GG37:GM37) -> 0 | AE36: =SUM('Avance Diario'!GN37:GT37) -> 0 | AF36: =SUM('Avance Diario'!GU37:HA37) -> 0 | AG36: =SUM('Avance Diario'!HB37:HE37) -> 0
C37: Avance acumulado % | D37: =SUM($D36:D36) -> 0 | E37: =SUM($D36:E36) -> 0 | F37: =SUM($D36:F36) -> 0 | G37: =SUM($D36:G36) -> 0 | H37: =SUM($D36:H36) -> 0 | I37: =SUM($D36:I36) -> 0 | J37: =SUM($D36:J36) -> 0 | K37: =SUM($D36:K36) -> 0 | ... AG37: =SUM($D36:AG36) -> 100
A38: 1.2.4.1.9.2.3 | B38: [M3] C / F1 / OC / Losa / C2 / Hormigón | C38: Avance parcial % | D38: =SUM('Avance Diario'!G39:M39) -> 0 | E38: =SUM('Avance Diario'!N39:T39) -> 0 | F38: =SUM('Avance Diario'!U39:AA39) -> 0 | G38: =SUM('Avance Diario'!AB39:AH39) -> 0 | H38: =SUM('Avance Diario'!AI39:AO39) -> 0 | I38: =SUM('Avance Diario'!AP39:AV39) -> 0 | J38: =SUM('Avance Diario'!AW39:BC39) -> 0 | K38: =SUM('Avance Diario'!BD39:BJ39) -> 0 | L38: =SUM('Avance Diario'!BK39:BQ39) -> 0 | M38: =SUM('Avance Diario'!BR39:BX39) -> 0 | N38: =SUM('Avance Diario'!BY39:CE39) -> 0 | O38: =SUM('Avance Diario'!CF39:CL39) -> 0 | P38: =SUM('Avance Diario'!CM39:CS39) -> 0 | Q38: =SUM('Avance Diario'!CT39:CZ39) -> 0 | R38: =SUM('Avance Diario'!DA39:DG39) -> 0 | S38: =SUM('Avance Diario'!DH39:DN39) -> 0 | T38: =SUM('Avance Diario'!DO39:DU39) -> 0 | U38: =SUM('Avance Diario'!DV39:EB39) -> 0 | V38: =SUM('Avance Diario'!EC39:EI39) -> 0 | W38: =SUM('Avance Diario'!EJ39:EP39) -> 100 | X38: =SUM('Avance Diario'!EQ39:EW39) -> 0 | Y38: =SUM('Avance Diario'!EX39:FD39) -> 0 | Z38: =SUM('Avance Diario'!FE39:FK39) -> 0 | AA38: =SUM('Avance Diario'!FL39:FR39) -> 0 | AB38: =SUM('Avance Diario'!FS39:FY39) -> 0 | AC38: =SUM('Avance Diario'!FZ39:GF39) -> 0 | AD38: =SUM('Avance Diario'!GG39:GM39) -> 0 | AE38: =SUM('Avance Diario'!GN39:GT39) -> 0 | AF38: =SUM('Avance Diario'!GU39:HA39) -> 0 | AG38: =SUM('Avance Diario'!HB39:HE39) -> 0
C39: Avance acumulado % | D39: =SUM($D38:D38) -> 0 | E39: =SUM($D38:E38) -> 0 | F39: =SUM($D38:F38) -> 0 | G39: =SUM($D38:G38) -> 0 | H39: =SUM($D38:H38) -> 0 | I39: =SUM($D38:I38) -> 0 | J39: =SUM($D38:J38) -> 0 | K39: =SUM($D38:K38) -> 0 | ... AG39: =SUM($D38:AG38) -> 100
